Workbook

Sheet Hoja1
C1: Referencia: | F1: 17 | I1: Maribel Gil modelista | L1: 0 a 1.5 | M1: 5 | N1: 1.05
C2: Tipo: | F2: BANDOLERA PARA DAMA | L2: 1.51 a 3 | M2: 10 | N2: 1.1
C3: Fecha: | F3: 44977 | L3: 3.01 a 5 | M3: 15 | N3: 1.15
C4: cliente | F4: SENA | L4: mas de 5 | M4: 20 | N4: 1.2
C5: numero de ficha | F5: celda de Producción | L5: tiras de mas de 80 cm | M5: 40 | N5: 1.4
A8: material | B8: numero del molde | C8: nombre del molde | D8: cantidad | E8: alto | F8: ancho | G8: alto x ancho = cm_2 | H8: dm^2 | I8: % desperdicio | J8: Total | L8: PENDIENTE FOTO
A9: cuero | B9: 1 | C9: espaldar | D9: 1 | E9: 23.5 | F9: 19.5 | G9: =E9*F9 -> 458.25 | H9: =G9/100 -> 4.5825 | I9: 1.1 | J9: =D9*H9*I9 -> 5.04075
B10: 2 | C10: frente | D10: 1 | E10: 25.5 | F10: 21.5 | G10: =E10*F10 -> 548.25 | H10: =G10/100 -> 5.4825 | I10: 1.1 | J10: =D10*H10*I10 -> 6.03075
B11: 6 | C11: FALSE | D11: 1 | E11: 45.7 | F11: 8 | G11: =E11*F11 -> 365.6 | H11: =G11/100 -> 3.656 | I11: 1.05 | J11: =D11*H11*I11 -> 3.8388 | T11: =119/28 -> 4.25
B12: 7 | C12: porta cremallera | D12: 2 | E12: 33.2 | F12: 4.1 | G12: =E12*F12 -> 136.12 | H12: =G12/100 -> 1.3612 | I12: 1.1 | J12: =D12*H12*I12 -> 2.99464
B13: 8 | C13: chapetas | D13: 3 | E13: 8.7 | F13: 6 | G13: =E13*F13 -> 52.2 | H13: =G13/100 -> 0.522 | I13: 1.1 | J13: =D13*H13*I13 -> 1.7226
B14: 9 | C14: vivo | D14: 2 | E14: 80 | F14: 2.5 | G14: =E14*F14 -> 200 | H14: =G14/100 -> 2 | I14: 1.05 | J14: =D14*H14*I14 -> 4.2
C15: correa | D15: 2 | E15: 80 | F15: 2.5 | G15: =E15*F15 -> 200 | H15: =G15/100 -> 2 | I15: 1.05 | J15: =D15*H15*I15 -> 4.2
G16: =E16*F16 -> 0 | H16: =G16/100 -> 0 | I16: 1.05 | J16: =D16*H16*I16 -> 0
G17: =E17*F17 -> 0 | H17: =G17/100 -> 0 | I17: 1.05 | J17: =D17*H17*I17 -> 0
G18: =E18*F18 -> 0 | H18: =G18/100 -> 0 | I18: 1.05 | J18: =D18*H18*I18 -> 0
G19: =E19*F19 -> 0 | H19: =G19/100 -> 0 | I19: 1.1 | J19: =D19*H19*I19 -> 0
G20: =E20*F20 -> 0 | H20: =G20/100 -> 0 | I20: 1.05 | J20: =D20*H20*I20 -> 0
B21: total cuero en dm_2 | J21: =SUM(J9:J20) -> 28.02754
A22: perimetros para consumo de hilo en cm | E22: =SUM(E9:E20) -> 296.6 | F22: =SUM(F9:F20) -> 64.1 | G22: =E22+F22 -> 360.7 | H22: =G22*2 -> 721.4
A24: material | B24: numero del molde | C24: nombre del molde | D24: cantidad | E24: alto | F24: ancho | G24: atlo x ancho=cm_2 | H24: dm^2 | I24: % desperdicio | J24: Total
A25: cambre | B25: 2 | C25: frente | D25: 1 | E25: 25.5 | F25: 21.5 | G25: =E25*F25 -> 548.25 | H25: =G25/100 -> 5.4825 | I25: 1.1 | J25: =D25*I25*H25 -> 6.03075
G26: =E26*F26 -> 0 | H26: =G26/100 -> 0 | I26: 1.05 | J26: =D26*I26*H26 -> 0
G27: =E27*F27 -> 0 | H27: =G27/100 -> 0 | I27: 1.05 | J27: =D27*I27*H27 -> 0
J28: =SUM(J25:J27) -> 6.03075
A30: material | B30: numero del molde | C30: nombre del molde | D30: cantidad | E30: alto | F30: ancho | G30: atlo x ancho=cm_2 | H30: % desperdicio | I30: Total
A31: FORRO | B31: 3 | C31: frente y espalda | D31: 2 | E31: 23.5 | F31: 19.5 | G31: =E31*F31 -> 458.25 | H31: 1.1 | I31: =D31*G31*H31 -> 1008.15
B32: 4 | C32: bolsillo interno | D32: 1 | E32: 22 | F32: 17 | G32: =E32*F32 -> 374 | H32: 1.1 | I32: =D32*G32*H32 -> 411.4
B33: 6 | C33: FALSE | D33: 1 | E33: 45.7 | F33: 8 | G33: =E33*F33 -> 365.6 | H33: 1.1 | I33: =D33*G33*H33 -> 402.16
B34: 7 | C34: porta cremallera | D34: 2 | E34: 33.2 | F34: 4.1 | G34: =E34*F34 -> 136.12 | H34: 1.1 | I34: =D34*G34*H34 -> 299.464
G35: =E35*F35 -> 0 | H35: 1.1 | I35: =D35*G35*H35 -> 0
G36: =E36*F36 -> 0 | H36: 1.1 | I36: =D36*G36*H36 -> 0
G37: =E37*F37 -> 0 | H37: 1.1 | I37: =D37*G37*H37 -> 0
B39: total FORRO en cm_2 | I39: =SUM(I31:I38) -> 2121.174
A41: material | B41: numero del molde | C41: nombre del molde | D41: cantidad | E41: alto | F41: ancho | G41: atlo x ancho=cm_2 | H41: % desperdicio | I41: Total
A42: cartulina | B42: 5 | C42: caja cierre | D42: 1 | E42: 17.2 | F42: 3.6 | G42: =E42*F42 -> 61.92 | H42: 1.1 | I42: =D42*G42*H42 -> 68.112
G43: =E43*F43 -> 0 | H43: 1.1 | I43: =D43*G43*H43 -> 0
G44: =E44*F44 -> 0 | H44: 1.1 | I44: =D44*G44*H44 -> 0
I45: =SUM(I42:I44) -> 68.112
A47: material | B47: numero del molde | C47: nombre del molde | D47: cantidad | E47: alto | F47: ancho | G47: atlo x ancho=cm_2 | H47: % desperdicio | I47: Total
...

Sheet Hoja2
C1: Referencia: | F1: =Hoja1!F1 -> 17 | I1: Maribel Gil modelista
C2: Tipo: | F2: =Hoja1!F2 -> BANDOLERA PARA DAMA
C3: Fecha: | F3: =Hoja1!F3 -> 44977
C4: cliente | F4: =Hoja1!F4 -> SENA
C5: numero de ficha | F5: =Hoja1!F5 -> celda de Producción
A8: MATERIAL | B8: UNIDAD DE MEDIDA | C8: CANTIDAD | D8: VALOR UNITARIO | E8: VALOR TOTAL $ | H8: material | I8: unidad de medida compra | J8: valor
A9: =Hoja1!A9 -> cuero | B9: dm^2 | C9: =Hoja1!J21 -> 28.02754 | D9: =J9 -> 0 | E9: =C9*D9 -> 0 | H9: =A9 -> cuero | I9: =B9 -> dm^2 | J9: 0
A10: =Hoja1!A25 -> cambre | B10: dm^2 | C10: =Hoja1!J28 -> 6.03075 | D10: =J10 -> 0 | E10: =C10*D10 -> 0 | H10: =A10 -> cambre | I10: =B10 -> dm^2 | J10: 0
A11: =Hoja1!A31 -> FORRO | B11: cm | C11: =Hoja1!I39/70 -> 30.302486 | D11: =J11/100 -> 150 | E11: =C11*D11 -> 4545.3729 | H11: =A11 -> FORRO | I11: metro | J11: 15000
A12: =Hoja1!A42 -> cartulina | B12: cm | C12: =Hoja1!I45/140 -> 0.48651429 | D12: =J12/100 -> 0 | E12: =C12*D12 -> 0 | H12: =A12 -> cartulina | I12: metro | J12: 0
A13: =Hoja1!A48 -> espuma #1 | B13: cm | C13: =Hoja1!I51/140 -> 2.1893143 | D13: =J13/100 -> 0 | E13: =C13*D13 -> 0 | H13: =A13 -> espuma #1 | I13: metro | J13: 0
A14: =Hoja1!A54 -> yumbolon | B14: cm | C14: =Hoja1!I57/100 -> 5.30904 | D14: =J14/100 -> 0 | E14: =C14*D14 -> 0 | H14: =A14 -> yumbolon | I14: metro | J14: 0
A15: cuadrante 11/2'' | B15: unid | C15: 2 | D15: =J15 -> 0 | E15: =C15*D15 -> 0 | H15: =A15 -> cuadrante 11/2'' | I15: unid | J15: 0
A16: trabilla 11/2'' | B16: unid | C16: 1 | D16: =J164 -> 0 | E16: =C16*D16 -> 0 | H16: =A16 -> trabilla 11/2'' | I16: unid | J16: 0
A17: cremallera #6 | B17: cm | C17: 34 | D17: =J17/100 -> 0 | E17: =C17*D17 -> 0 | H17: =A17 -> cremallera #6 | I17: metro | J17: 0
A18: llave #6 | B18: unid | C18: 1 | D18: =J18 -> 0 | E18: =C18*D18 -> 0 | H18: =A18 -> llave #6 | I18: unid | J18: 0
A19: cremallera #3 | B19: cm | C19: 17 | D19: =J19/100 -> 0 | E19: =C19*D19 -> 0 | H19: =A19 -> cremallera #3 | I19: metro | J19: 0
A20: llave #3 | B20: unid | C20: 1 | D20: =J20 -> 0 | E20: =C20*D20 -> 0 | H20: =A20 -> llave #3 | I20: unid | J20: 0
A21: embono plastico | B21: cm | C21: =78*2 -> 156 | D21: =J21/500 -> 0 | E21: =C21*D21 -> 0 | H21: =A21 -> embono plastico | I21: madeja x 50mt | J21: 0
A22: reata 11/2'' | B22: cm | C22: 160 | D22: =J22/500 -> 0 | E22: =C22*D22 -> 0 | H22: =A22 -> reata 11/2'' | I22: metro | J22: 0
A23: hilo x 3000 | B23: metros | C23: =(Hoja1!H22+(160*2))*3/100 -> 31.242 | D23: =J23/3000 -> 0 | E23: =C23*D23 -> 0 | H23: =A23 -> hilo x 3000 | I23: cono | J23: 0
A24: pegante x 3000 | B24: gramos | C24: 30 | D24: =J24/3000 -> 0 | E24: =C24*D24 -> 0 | H24: =A24 -> pegante x 3000 | I24: galon | J24: 0
A25: mano de obra | C25: 1 | D25: =J25 -> 0 | E25: =C25*D25 -> 0 | H25: =A25 -> mano de obra | I25: hora/persona | J25: 0
A26: empaque (cambre) | D26: =J26/100 -> 0 | E26: =C26*D26 -> 0 | H26: =A26 -> empaque (cambre) | I26: metro | J26: 0
A27: inversión | E27: =SUM(E9:E26) -> 4545.3729
A28: costos fijos | C28: 0 | E28: =E27*C28 -> 0
A29: costos variables e indirectos | C29: 0 | E29: =E27*C29 -> 0 | G29: punto de equilibrio | H29: minimo de productos que tengo que vender para cumplir con todas las obligaciones sin obtener ganancia
A30: ganancia | C30: 0 | E30: =E27*C30 -> 0
A31: costo sugerido de venta | E31: =SUM(E27:E30) -> 4545.3729
A34: tipo de maquina | B34: plana | C34: fecha inicio
A35: tipo de aguja | B35: cortante | C35: fecha entrega
A36: numero de aguja | B36: 110 | C36: cantidad solicitada
A37: calibre hilo | B37: 40
A38: color hilo | B38: a tono
A39: corte
A40: prearme
A41: armado
A42: costura
