Workbook

Sheet Hoja1
C1: Referencia: | F1: 14 | I1: Maribel Gil modelista | L1: 0 a 1.5 | M1: 5 | N1: 1.05
C2: Tipo: | F2: BILLETERA HOMBRE CON TARJETERO | L2: 1.51 a 3 | M2: 10 | N2: 1.1
C3: Fecha: | F3: 44951 | L3: 3.01 a 5 | M3: 15 | N3: 1.15
C4: cliente | F4: SENA | L4: mas de 5 | M4: 20 | N4: 1.2
C5: numero de ficha | F5: CELDA DE PRODUCCIÓN | L5: tiras de mas de 80 cm | M5: 40 | N5: 1.4
A9: material | B9: numero del molde | C9: nombre del molde | D9: cantidad | E9: alto | F9: ancho | G9: alto x ancho = cm_2 | H9: dm_2 | I9: % desperdicio | J9: Total | L9: PENDIENTE FOTO
A10: cuero | B10: 6 | C10: CENTRO | D10: 1 | E10: 4 | F10: 9 | G10: =E10*F10 -> 36 | H10: =G10/100 -> 0.36 | I10: 1.05 | J10: =D10*H10*I10 -> 0.378
B11: 7 | C11: TRAJETERO TOPE | D11: 2 | E11: 10.5 | F11: 2.7 | G11: =E11*F11 -> 28.35 | H11: =G11/100 -> 0.2835 | I11: 1.05 | J11: =D11*H11*I11 -> 0.59535
B12: 8 | C12: TARJETEROS | D12: 4 | E12: 10.5 | F12: 2.7 | G12: =E12*F12 -> 28.35 | H12: =G12/100 -> 0.2835 | I12: 1.05 | J12: =D12*H12*I12 -> 1.1907
B13: 9 | C13: CELLERO | D13: 2 | E13: 10.4 | F13: 6 | G13: =E13*F13 -> 62.4 | H13: =G13/100 -> 0.624 | I13: 1.05 | J13: =D13*H13*I13 -> 1.3104
B14: 13 | C14: BOLSILLO ESPALDAR | D14: 2 | E14: 4 | F14: 11.4 | G14: =E14*F14 -> 45.6 | H14: =G14/100 -> 0.456 | I14: 1.05 | J14: =D14*H14*I14 -> 0.9576
B15: 14 | C15: COMPLMENTO BOLSILLO ESPALDAR | D15: 1 | E15: 8.9 | F15: 11.4 | G15: =E15*F15 -> 101.46 | H15: =G15/100 -> 1.0146 | I15: 1.05 | J15: =D15*H15*I15 -> 1.06533
B16: 15 | C16: COMPLEMENTO SUPERIOR ESPALDAR | D16: 1 | E16: 14.4 | F16: 8.5 | G16: =E16*F16 -> 122.4 | H16: =G16/100 -> 1.224 | I16: 1.05 | J16: =D16*H16*I16 -> 1.2852
B17: 17 | C17: COMPLEMENTO INFERIOR ESPALDAR | D17: 1 | E17: 14.3 | F17: 3.8 | G17: =E17*F17 -> 54.34 | H17: =G17/100 -> 0.5434 | I17: 1.05 | J17: =D17*H17*I17 -> 0.57057
B18: 23 | C18: TOPE TARJETERO EXTRAIBLE | D18: 2 | E18: 9.5 | F18: 1.9 | G18: =E18*F18 -> 18.05 | H18: =G18/100 -> 0.1805 | I18: 1.05 | J18: =D18*H18*I18 -> 0.37905
B19: 24 | C19: VISOR TARJETERO EXTRAIBLE | D19: 1 | E19: 9.5 | F19: 6.9 | G19: =E19*F19 -> 65.55 | H19: =G19/100 -> 0.6555 | I19: 1.05 | J19: =D19*H19*I19 -> 0.688275
B20: 26 | C20: TARJETERO EXTRAIBLE | D20: 1 | E20: 9.5 | F20: 2.2 | G20: =E20*F20 -> 20.9 | H20: =G20/100 -> 0.209 | I20: 1.05 | J20: =D20*H20*I20 -> 0.21945
B21: 27 | C21: CELLERO TARJETERO EXTRAIBLE | D21: 1 | E21: 9.5 | F21: 5.8 | G21: =E21*F21 -> 55.1 | H21: =G21/100 -> 0.551 | I21: 1.05 | J21: =D21*H21*I21 -> 0.57855
G22: =E22*F22 -> 0 | H22: =G22/100 -> 0 | I22: 1.05 | J22: =D22*H22*I22 -> 0
G23: =E23*F23 -> 0 | H23: =G23/100 -> 0 | I23: 1.1 | J23: =D23*H23*I23 -> 0
G24: =E24*F24 -> 0 | H24: =G24/100 -> 0 | I24: 1.1 | J24: =D24*H24*I24 -> 0
G25: =E25*F25 -> 0 | H25: =G25/100 -> 0 | I25: 1.05 | J25: =D25*H25*I25 -> 0
B26: total cuero en dm_2 | J26: =SUM(J10:J25) -> 9.218475
A27: perimetros para consumo de hilo en cm | E27: =SUM(E10:E25) -> 115 | F27: =SUM(F10:F25) -> 72.3 | G27: =E27+F27 -> 187.3 | H27: =G27*2 -> 374.6
A29: material | B29: numero del molde | C29: nombre del molde | D29: cantidad | E29: alto | F29: ancho | G29: atlo x ancho=cm_2 | H29: dm_2 | I29: % desperdicio | J29: Total
A30: CUERO B | B30: 16 | C30: TIRA ESPALDAR | D30: 1 | E30: 14.3 | F30: 1.5 | G30: =E30*F30 -> 21.45 | H30: =G30/100 -> 0.2145 | I30: 1.05 | J30: =D30*I30*H30 -> 0.225225
G31: =E31*F31 -> 0 | H31: 1.1 | J31: =D31*G31*H31 -> 0
B32: total cuero en dm_2 | J32: =SUM(J30:J31) -> 0.225225
A34: material | B34: numero del molde | C34: nombre del molde | D34: cantidad | E34: alto | F34: ancho | G34: atlo x ancho=cm_2 | H34: % desperdicio | I34: Total
A35: MALLA | B35: 25 | C35: VISOR | D35: 1 | E35: 9.5 | F35: 6 | G35: =E35*F35 -> 57 | H35: 1.1 | I35: =D35*G35*H35 -> 62.7
G36: =E36*F36 -> 0 | H36: 1.1 | I36: =D36*G36*H36 -> 0
I37: =SUM(I35:I36) -> 62.7
A40: material | B40: numero del molde | C40: nombre del molde | D40: cantidad | E40: alto | F40: ancho | G40: atlo x ancho=cm_2 | H40: % desperdicio | I40: Total
A41: FORRO | B41: 3 | C41: ESPALDAR | D41: 1 | E41: 22.7 | F41: 8.7 | G41: =E41*F41 -> 197.49 | H41: 1.1 | I41: =D41*G41*H41 -> 217.239
B42: 4 | C42: DIVISION | D42: 1 | E42: 22.1 | F42: 14.7 | G42: =E42*F42 -> 324.87 | H42: 1.1 | I42: =D42*G42*H42 -> 357.357
B43: 5 | C43: CENTRO | D43: 1 | E43: 21.3 | F43: 8.2 | G43: =E43*F43 -> 174.66 | H43: 1.1 | I43: =D43*G43*H43 -> 192.126
B44: 10 | C44: TARJETEROS | D44: 4 | E44: 9.2 | F44: 10.5 | G44: =E44*F44 -> 96.6 | H44: 1.1 | I44: =D44*G44*H44 -> 425.04
B45: 11 | C45: CELLEROS | D45: 2 | E45: 9.5 | F45: 5.2 | G45: =E45*F45 -> 49.4 | H45: 1.1 | I45: =D45*G45*H45 -> 108.68
B46: 12 | C46: BATA | D46: 2 | E46: 10.4 | F46: 8.2 | G46: =E46*F46 -> 85.28 | H46: 1.1 | I46: =D46*G46*H46 -> 187.616
B47: 18 | C47: BOLSILLO ESPALDAR | D47: 1 | E47: 8.8 | F47: 8.7 | G47: =E47*F47 -> 76.56 | H47: 1.1 | I47: =D47*G47*H47 -> 84.216
...

Sheet Hoja2
C1: Referencia: | F1: =Hoja1!F1 -> 14 | I1: Maribel Gil modelista
C2: Tipo: | F2: =Hoja1!F2 -> BILLETERA HOMBRE CON TARJETERO
C3: Fecha: | F3: =Hoja1!F3 -> 44951
C4: cliente | F4: =Hoja1!F4 -> SENA
C5: numero de ficha | F5: =Hoja1!F5 -> CELDA DE PRODUCCIÓN
A8: MATERIAL | B8: UNIDAD DE MEDIDA | C8: CANTIDAD | D8: VALOR UNITARIO | E8: VALOR TOTAL $ | H8: material | I8: unidad de medida compra | J8: valor
A9: =Hoja1!A10 -> cuero | B9: dm_2 | C9: =Hoja1!J26 -> 9.218475 | D9: =#REF! -> #REF! | E9: =C9*D9 -> #REF! | H9: =A9 -> cuero | I9: =B9 -> dm_2
A10: =Hoja1!A30 -> CUERO B | B10: dm_2 | C10: =Hoja1!J32 -> 0.225225 | D10: =J10 | E10: =C10*D10 -> 0 | H10: =A10 -> CUERO B | I10: dm_2
A11: =Hoja1!A35 -> MALLA | B11: cm | C11: =Hoja1!I37/140 -> 0.44785714 | D11: =J9/100 -> 0 | E11: =C11*D11 -> 0 | H11: =A11 -> MALLA | I11: metro
A12: =Hoja1!A41 -> FORRO | B12: cm | C12: =Hoja1!I55/140 -> 13.644007 | D12: =J12/100 -> 0 | E12: =C12*D12 -> 0 | H12: =A12 -> FORRO | I12: metro
A13: =Hoja1!A58 | B13: cm | C13: =Hoja1!I60/140 -> 0 | D13: =J13/100 -> 0 | E13: =C13*D13 -> 0 | H13: =A13 | I13: metro
D14: =J14/100 -> 0 | E14: =C14*D14 -> 0 | H14: =A14 | I14: metro
A15: hilo x 3000 | B15: metros | C15: =(Hoja1!H27)*3 -> 1123.8 | D15: =J15/3000 -> 0 | E15: =C15*D15 -> 0 | H15: =A15 -> hilo x 3000 | I15: cono
A16: pegante x 3000 | B16: gramos | C16: 58 | D16: =J16/3000 -> 0 | E16: =C16*D16 -> 0 | H16: =A16 -> pegante x 3000 | I16: galon | J16: 0
A17: mano de obra | C17: 1 | D17: 0 | E17: =C17*D17 -> 0 | H17: =A17 -> mano de obra
A18: empaque | H18: =A18 -> empaque
A19: inversión | E19: =SUM(E9:E17) -> #REF!
A20: costos fijos | C20: 0.1 | E20: =E19*C20 -> #REF!
A21: costos variables e indirectos | C21: 0.1 | E21: =E19*C21 -> #REF! | G21: punto de equilibrio | H21: minimo de productos que tengo que vender para cumplir con todas las obligaciones sin obtener ganancia
A22: ganancia | C22: 0.1 | E22: =E19*C22 -> #REF!
A23: costo sugerido de venta | E23: =SUM(E19:E22) -> #REF!
A26: tipo de maquina | B26: plana | C26: fecha inicio | D26: 44963
A27: tipo de aguja | B27: cortante | C27: fecha entrega | D27: 44967
A28: numero de aguja | B28: 90 | C28: cantidad solicitada | D28: 17 unidades
A29: calibre hilo | B29: 60
A30: color hilo | B30: a tono
A31: corte | B31: Santiago y Janer | C31: Personas encargadas de liderar el proceso, pero en cuanto termina este se incorporan a uno de los otros equipos
A32: prearme | B32: Melissa y Juliana
A33: armado | B33: Nanasury y Cristina
A34: costura | B34: Sara y Alejandra
