Workbook

Sheet Hoja1
C1: Referencia: | F1: 1 | I1: Maribel Gil modelista | L1: 0 a 1.5 | M1: 5 | N1: 1.05
C2: Tipo: | F2: lonchera en lona | L2: 1.51 a 3 | M2: 10 | N2: 1.1
C3: Fecha: | F3: 45012 | L3: 3.01 a 5 | M3: 15 | N3: 1.15
C4: cliente | F4: SENA | L4: mas de 5 | M4: 20 | N4: 1.2
C5: numero de ficha | F5: celda de pcc | L5: tiras de mas de 80 cm | M5: 40 | N5: 1.4
A8: material | B8: numero del molde | C8: nombre del molde | D8: cantidad | E8: alto | F8: ancho | G8: alto x ancho = cm_2 | H8: % desperdicio | I8: Total
A9: lona sintetica | B9: 1 | C9: FALSE | D9: 2 | E9: 16 | F9: 20 | G9: =E9*F9 -> 320 | H9: 1.1 | I9: =D9*G9*H9 -> 704
B10: 4 | C10: tapa | D10: 1 | E10: 20 | F10: 18.9 | G10: =E10*F10 -> 378 | H10: 1.1 | I10: =D10*G10*H10 -> 415.8
B11: 5 | C11: complemento tapa | D11: 1 | E11: 24 | F11: 26.6 | G11: =E11*F11 -> 638.4 | H11: 1.1 | I11: =D11*G11*H11 -> 702.24
B12: 6 | C12: fondo | D12: 1 | E12: 24 | F12: 38.2 | G12: =E12*F12 -> 916.8 | H12: 1.1 | I12: =D12*G12*H12 -> 1008.48
C13: vivo | D13: 2 | E13: 64 | F13: 2.5 | G13: =E13*F13 -> 160 | H13: 1.1 | I13: =D13*G13*H13 -> 352
G14: =E14*F14 -> 0 | H14: 1.1 | I14: =D14*G14*H14 -> 0
G15: =E15*F15 -> 0 | H15: 1.1 | I15: =D15*G15*H15 -> 0
G16: =E16*F16 -> 0 | H16: 1.1 | I16: =D16*G16*H16 -> 0
B17: total sintético en cm_2 | I17: =SUM(I9:I16) -> 3182.52
A18: perimetros para consumo de hilo en cm | E18: =SUM(E9:E16) -> 148 | F18: =SUM(F9:F16) -> 106.2 | G18: =E18+F18 -> 254.2
A20: material | B20: numero del molde | C20: nombre del molde | D20: cantidad | E20: alto | F20: ancho | G20: alto x ancho = cm_2 | H20: % desperdicio | I20: Total
A21: yumbolon #3 | B21: 7 | C21: refuerzo falso | D21: 2 | E21: 11 | F21: 15 | G21: =E21*F21 -> 165 | H21: 1.1 | I21: =D21*G21*H21 -> 363
B22: 8 | C22: refuerzo tapa | D22: 1 | E22: 13.5 | F22: 15 | G22: =E22*F22 -> 202.5 | H22: 1.1 | I22: =D22*G22*H22 -> 222.75
B23: 9 | C23: refuerzo cuerpo | D23: 1 | E23: 19 | F23: 33.2 | G23: =E23*F23 -> 630.8 | H23: 1.1 | I23: =D23*G23*H23 -> 693.88
B24: total sintético en cm_2 | I24: =SUM(I21:I23) -> 1279.63
A25: perimetros para consumo de hilo en cm | E25: =SUM(E7:E23) -> 339.5 | F25: =SUM(F7:F23) -> 275.6 | G25: =E25+F25 -> 615.1
A30: material | B30: numero del molde | C30: nombre del molde | D30: cantidad | E30: alto | F30: ancho | G30: atlo x ancho=cm_2 | H30: % desperdicio | I30: Total
G31: =E31*F31 -> 0 | H31: 1.1 | I31: =D31*G31*H31 -> 0
G32: =E32*F32 -> 0 | H32: 1.1 | I32: =D32*G32*H32 -> 0
I33: =SUM(I31:I32) -> 0
A35: material | B35: numero del molde | C35: nombre del molde | D35: cantidad | E35: alto | F35: ancho | G35: atlo x ancho=cm_2 | H35: % desperdicio | I35: Total
G36: =E36*F36 -> 0 | H36: 1.1 | I36: =D36*G36*H36 -> 0
G37: =E37*F37 -> 0 | H37: 1.1 | I37: =D37*G37*H37 -> 0
I38: =SUM(I36:I37) -> 0
A41: material | B41: numero del molde | C41: nombre del molde | D41: cantidad | E41: alto | F41: ancho | G41: atlo x ancho=cm_2 | H41: % desperdicio | I41: Total
A42: seda 30100 | B42: 1 | C42: FALSE | D42: 2 | E42: 16 | F42: 20 | G42: =E42*F42 -> 320 | H42: 1.1 | I42: =D42*G42*H42 -> 704
B43: 3 | C43: bolsillo delantero | D43: 1 | E43: 24 | F43: 24 | G43: =E43*F43 -> 576 | H43: 1.1 | I43: =D43*G43*H43 -> 633.6
B44: 4 | C44: tapa | D44: 1 | E44: 20 | F44: 18.9 | G44: =E44*F44 -> 378 | H44: 1.1 | I44: =D44*G44*H44 -> 415.8
B45: 5 | C45: complemento tapa | D45: 1 | E45: 24 | F45: 26.6 | G45: =E45*F45 -> 638.4 | H45: 1.1 | I45: =D45*G45*H45 -> 702.24
B46: 6 | C46: fondo | D46: 1 | E46: 24 | F46: 38.2 | G46: =E46*F46 -> 916.8 | H46: 1.1 | I46: =D46*G46*H46 -> 1008.48
G47: =E47*F47 -> 0 | H47: 1.1 | I47: =D47*G47*H47 -> 0
G48: =E48*F48 -> 0 | H48: 1.1 | I48: =D48*G48*H48 -> 0
B50: total FORRO en cm_2 | I50: =SUM(I42:I49) -> 3464.12
A52: material | B52: numero del molde | C52: nombre del molde | D52: cantidad | E52: alto | F52: ancho | G52: atlo x ancho=cm_2 | H52: % desperdicio | I52: Total
...

Sheet Hoja2
C1: Referencia: | F1: =Hoja1!F1 -> 1 | I1: Maribel Gil modelista
C2: Tipo: | F2: =Hoja1!F2 -> lonchera en lona
C3: Fecha: | F3: =Hoja1!F3 -> 45012
C4: cliente | F4: =Hoja1!F4 -> SENA
C5: numero de ficha | F5: =Hoja1!F5 -> celda de pcc
A8: MATERIAL | B8: UNIDAD DE MEDIDA | C8: CANTIDAD | D8: VALOR UNITARIO | E8: VALOR TOTAL $ | H8: material | I8: unidad de medida compra | J8: valor
A9: =Hoja1!A9 -> lona sintetica | B9: cm | C9: =Hoja1!I17/140 -> 22.732286 | D9: =J9/100 -> 0 | E9: =C9*D9 -> 0 | H9: =A9 -> lona sintetica | I9: metro | J9: 0
A10: =Hoja1!A21 -> yumbolon #3 | B10: cm | C10: =Hoja1!I24/140 -> 9.1402143 | D10: =J10/100 -> 0 | E10: =C10*D10 -> 0 | H10: =A10 -> yumbolon #3 | I10: metro | J10: 0
A11: =Hoja1!A31 -> 0 | B11: cm | C11: =Hoja1!I33/70 -> 0 | D11: =J11/100 -> 0 | E11: =C11*D11 -> 0 | H11: =A11 -> 0 | I11: metro | J11: 0
A12: =Hoja1!A36 -> 0 | B12: cm | C12: =Hoja1!I38/140 -> 0 | D12: =J12/100 -> 0 | E12: =C12*D12 -> 0 | H12: =A12 -> 0 | I12: metro | J12: 0
A13: =Hoja1!A42 -> seda 30100 | B13: cm | C13: =Hoja1!I50/140 -> 24.743714 | D13: =J13/100 -> 0 | E13: =C13*D13 -> 0 | H13: =A13 -> seda 30100 | I13: metro | J13: 0
B14: cm | C14: =Hoja1!I55/140 -> 0 | D14: =J14/100 -> 0 | E14: =C14*D14 -> 0 | H14: =A14 -> 0 | I14: metro | J14: 0
A15: cremallera #6 | B15: cm | C15: =54+24 -> 78 | D15: =J15/100 -> 0 | E15: =C15*D15 -> 0 | H15: =A15 -> cremallera #6 | I15: metro | J15: 0
A16: llave #6 | B16: unid | C16: 2 | D16: =J16 -> 0 | E16: =C16*D16 -> 0 | H16: =A16 -> llave #6 | I16: unidad | J16: 0
A17: trabilla 1 1/2'' | B17: unid | C17: 1 | D17: =J17 -> 0 | E17: =C17*D17 -> 0 | H17: =A17 -> trabilla 1 1/2'' | I17: unidad | J17: 0
A18: cuadrante 1 1/2'' | B18: unid | C18: 1 | D18: =J18 -> 0 | E18: =C18*D18 -> 0 | H18: =A18 -> cuadrante 1 1/2'' | I18: unidad | J18: 0
A19: reata 1 1/2'' | B19: cm | C19: =17+17+8+20+160 -> 222 | D19: =J19/100 -> 0 | E19: =C19*D19 -> 0 | H19: =A19 -> reata 1 1/2'' | I19: metro | J19: 0
A20: hilo x 3000 | B20: metros | C20: =(Hoja1!G18+Hoja1!G25)*3/100 -> 26.079 | D20: =J20/3000 -> 0 | E20: =C20*D20 -> 0 | H20: =A20 -> hilo x 3000 | I20: cono | J20: 0
A21: pegante x 3000 | B21: gramos | C21: 58 | D21: =J21/3000 -> 0 | E21: =C21*D21 -> 0 | H21: =A21 -> pegante x 3000 | I21: galon | J21: 0
A22: mano de obra | C22: 1 | D22: 0 | E22: =C22*D22 -> 0 | H22: =A22 -> mano de obra | J22: 0
A23: empaque | B23: unidad | C23: 1 | D23: =J23 -> 0 | E23: =C23*D23 -> 0 | H23: =A23 -> empaque | J23: 0
A24: inversión | E24: =SUM(E9:E22) -> 0
A25: costos fijos | C25: 0 | E25: =E24*C25 -> 0
A26: costos variables e indirectos | C26: 0 | E26: =E24*C26 -> 0 | G26: punto de equilibrio | H26: minimo de productos que tengo que vender para cumplir con todas las obligaciones sin obtener ganancia
A27: ganancia | C27: 0 | E27: =E24*C27 -> 0
A28: costo sugerido de venta | E28: =SUM(E24:E27) -> 0
A31: tipo de maquina | B31: plana
A32: tipo de aguja | B32: bola
A33: numero de aguja | B33: 110
A34: calibre hilo | B34: 40-60
A35: color hilo | B35: a tono
A36: corte
A37: prearme
A38: armado
A39: costura
