Workbook
Name ADHESIVOS_Solventes: BD!$B$8:$B$18
Name AdheySol: BD!$B$7
Name Aux_Med: BD!$B$104
Name CATEGORIAS: Listas!$I$2:$I$12
Name Cuer_: BD!$B$401
Name CUERO: BD!$B$402:$B$424
Name Herraj_: BD!$B$444
Name HERRAJES: BD!$B$445:$B$886
Name Herram_: BD!$B$946
Name HERRAMIENTAS_: Tabla13[Material]
Name INSUMOS_COMPL_: BD!$B$985:$B$1021
Name Materiales: BD!$B$6:$B$1200
Name Observaciones: Listas!$G$2:$G$12
Name quimic_: BD!$B$1056
Name QUÍMICOS: BD!$B$1057:$B$1123
Name SECUNDARIO: BD!$B$105:$B$218
Name Sin_Tex: BD!$B$893
Name SiNTETICOS_TEXTILES: BD!$B$894:$B$925
Name SUELAS: Tabla5[Material]
Name T_comp_Aux_AD: BD!$A$8:$J$18
Name Tabla_Completa: BD!$A$6:'BD'!$J$1200
Name Total_AdhySol: BD!$B$6
Name Total_Cuero: BD!$B$400
Name Total_Herrajes: BD!$B$443
Name Total_Herramientas: BD!$B$945
Name Total_Ins_Compl: BD!$B$983
Name Total_SECUNDARIO_MEDULAR: BD!$B$103
Name Total_Sint_y_Tex: BD!$B$892
Name Unidades: Listas!$B$3:$B$28

Sheet Solicitar
A1: NOMBRE DEL PRODUCTO | E1: Bota 1 | L1: FECHA DE ELABORACION | O1: 45936
A2: VALOR DE UNA UNIDAD ($) | D2: =IF(K2="","",(SUM(W7:Y25)-(SUMIF(U7:V25,"Restar_Pedido",W7:Y25)))/$K$2) -> 33432.466 | G2: CANTIDAD A PRODUCIR | K2: 1 | M2: VALOR PRODUCCION($) | O2: =IFERROR(IF(K2=0,"",D2*K2),"") -> 33432.466
A4: Categoria del Insumo | D4: MATERIALES E INSUMOS. | O4: UNIDAD DE MEDIDA | Q4: CANTIDAD PEDIDA para: Un solo producto
S5: Ayuda de Cálculo | V5: =IF(K2="","",1/K2) -> 1 | X5: 1 | Y5: =IFERROR((V5*X5)," ") -> 1
S6: Entregar | U6: Observaciones | W6: Valor materiales (S)
A7: CUERO | D7: NOBUCK | O7: =IFERROR(IF(D7="","",INDEX(Tabla_Completa,MATCH(D7,Materiales,0),6)),"") -> dm2 | Q7: 1.4 | S7: =IFERROR(IF(Q7="Unidad","1",(Q7*$K$2)),"") -> 1.4 | U7: morado | W7: =IFERROR(IF(D7="","",INDEX(Tabla_Completa,MATCH(Solicitar!D7,Materiales,0),7)*S7),"") -> 1680
A8: CUERO | D8: NOBUCK | O8: =IFERROR(IF(D8="","",INDEX(Tabla_Completa,MATCH(D8,Materiales,0),6)),"") -> dm2 | Q8: 1.7 | S8: =IFERROR(IF(Q8="Unidad","1",(Q8*$K$2)),"") -> 1.7 | U8: negro | W8: =IFERROR(IF(D8="","",INDEX(Tabla_Completa,MATCH(Solicitar!D8,Materiales,0),7)*S8),"") -> 2040
A9: SiNTETICOS_TEXTILES | D9: FORRO PIQUET | O9: =IFERROR(IF(D9="","",INDEX(Tabla_Completa,MATCH(D9,Materiales,0),6)),"") -> cm2 | Q9: 2.6 | S9: =IFERROR(IF(Q9="Unidad","1",(Q9*$K$2)),"") -> 2.6 | U9: Negro | W9: =IFERROR(IF(D9="","",INDEX(Tabla_Completa,MATCH(Solicitar!D9,Materiales,0),7)*S9),"") -> 5.2029714
A10: SECUNDARIO | D10: ESPUMA MULTIFORM DENSIDAD 40 DE 5 mm | O10: =IFERROR(IF(D10="","",INDEX(Tabla_Completa,MATCH(D10,Materiales,0),6)),"") -> cm2 | Q10: 1.6 | S10: =IFERROR(IF(Q10="Unidad","1",(Q10*$K$2)),"") -> 1.6 | W10: =IFERROR(IF(D10="","",INDEX(Tabla_Completa,MATCH(Solicitar!D10,Materiales,0),7)*S10),"") -> 1.6
A11: SECUNDARIO | D11: HILO NYLON #40 | O11: =IFERROR(IF(D11="","",INDEX(Tabla_Completa,MATCH(D11,Materiales,0),6)),"") -> Cono | Q11: 1 | S11: =IFERROR(IF(Q11="Unidad","1",(Q11*$K$2)),"") -> 1 | U11: Negro | W11: =IFERROR(IF(D11="","",INDEX(Tabla_Completa,MATCH(Solicitar!D11,Materiales,0),7)*S11),"") -> 7266.6667
A12: SECUNDARIO | D12: HILO NYLON #40 | O12: =IFERROR(IF(D12="","",INDEX(Tabla_Completa,MATCH(D12,Materiales,0),6)),"") -> Cono | Q12: 1 | S12: =IFERROR(IF(Q12="Unidad","1",(Q12*$K$2)),"") -> 1 | U12: verde | W12: =IFERROR(IF(D12="","",INDEX(Tabla_Completa,MATCH(Solicitar!D12,Materiales,0),7)*S12),"") -> 7266.6667
A13: SECUNDARIO | D13: HILO NYLON #60 | O13: =IFERROR(IF(D13="","",INDEX(Tabla_Completa,MATCH(D13,Materiales,0),6)),"") -> Cono | Q13: 1 | S13: =IFERROR(IF(Q13="Unidad","1",(Q13*$K$2)),"") -> 1 | U13: negro | W13: =IFERROR(IF(D13="","",INDEX(Tabla_Completa,MATCH(Solicitar!D13,Materiales,0),7)*S13),"") -> 7266.665
A14: SECUNDARIO | D14: HILO NYLON #60 | O14: =IFERROR(IF(D14="","",INDEX(Tabla_Completa,MATCH(D14,Materiales,0),6)),"") -> Cono | Q14: 1 | S14: =IFERROR(IF(Q14="Unidad","1",(Q14*$K$2)),"") -> 1 | U14: verde | W14: =IFERROR(IF(D14="","",INDEX(Tabla_Completa,MATCH(Solicitar!D14,Materiales,0),7)*S14),"") -> 7266.665
A15: SECUNDARIO | D15: CORDON ENCERADO NEGRO LARGO | O15: =IFERROR(IF(D15="","",INDEX(Tabla_Completa,MATCH(D15,Materiales,0),6)),"") -> Par | Q15: 1 | S15: =IFERROR(IF(Q15="Unidad","1",(Q15*$K$2)),"") -> 1 | W15: =IFERROR(IF(D15="","",INDEX(Tabla_Completa,MATCH(Solicitar!D15,Materiales,0),7)*S15),"") -> 639
O16: =IFERROR(IF(D16="","",INDEX(Tabla_Completa,MATCH(D16,Materiales,0),6)),"") | S16: =IFERROR(IF(Q16="Unidad","1",(Q16*$K$2)),"") -> 0 | W16: =IFERROR(IF(D16="","",INDEX(Tabla_Completa,MATCH(Solicitar!D16,Materiales,0),7)*S16),"")
O17: =IFERROR(IF(D17="","",INDEX(Tabla_Completa,MATCH(D17,Materiales,0),6)),"") | S17: =IFERROR(IF(Q17="Unidad","1",(Q17*$K$2)),"") -> 0 | W17: =IFERROR(IF(D17="","",INDEX(Tabla_Completa,MATCH(Solicitar!D17,Materiales,0),7)*S17),"")
O18: =IFERROR(IF(D18="","",INDEX(Tabla_Completa,MATCH(D18,Materiales,0),6)),"") | S18: =IFERROR(IF(Q18="Unidad","1",(Q18*$K$2)),"") -> 0 | W18: =IFERROR(IF(D18="","",INDEX(Tabla_Completa,MATCH(Solicitar!D18,Materiales,0),7)*S18),"")
O19: =IFERROR(IF(D19="","",INDEX(Tabla_Completa,MATCH(D19,Materiales,0),6)),"") | S19: =IFERROR(IF(Q19="Unidad","1",(Q19*$K$2)),"") -> 0 | W19: =IFERROR(IF(D19="","",INDEX(Tabla_Completa,MATCH(Solicitar!D19,Materiales,0),7)*S19),"")
O20: =IFERROR(IF(D20="","",INDEX(Tabla_Completa,MATCH(D20,Materiales,0),6)),"") | S20: =IFERROR(IF(Q20="Unidad","1",(Q20*$K$2)),"") -> 0 | W20: =IFERROR(IF(D20="","",INDEX(Tabla_Completa,MATCH(Solicitar!D20,Materiales,0),7)*S20),"")
O21: =IFERROR(IF(D21="","",INDEX(Tabla_Completa,MATCH(D21,Materiales,0),6)),"") | S21: =IFERROR(IF(Q21="Unidad","1",(Q21*$K$2)),"") -> 0 | W21: =IFERROR(IF(D21="","",INDEX(Tabla_Completa,MATCH(Solicitar!D21,Materiales,0),7)*S21),"")
O22: =IFERROR(IF(D22="","",INDEX(Tabla_Completa,MATCH(D22,Materiales,0),6)),"") | S22: =IFERROR(IF(Q22="Unidad","1",(Q22*$K$2)),"") -> 0 | W22: =IFERROR(IF(D22="","",INDEX(Tabla_Completa,MATCH(Solicitar!D22,Materiales,0),7)*S22),"")
O23: =IFERROR(IF(D23="","",INDEX(Tabla_Completa,MATCH(D23,Materiales,0),6)),"") | S23: =IFERROR(IF(Q23="Unidad","1",(Q23*$K$2)),"") -> 0 | W23: =IFERROR(IF(D23="","",INDEX(Tabla_Completa,MATCH(Solicitar!D23,Materiales,0),7)*S23),"")
O24: =IFERROR(IF(D24="","",INDEX(Tabla_Completa,MATCH(D24,Materiales,0),6)),"") | S24: =IFERROR(IF(Q24="Unidad","1",(Q24*$K$2)),"") -> 0 | W24: =IFERROR(IF(D24="","",INDEX(Tabla_Completa,MATCH(Solicitar!D24,Materiales,0),7)*S24),"")
O25: =IFERROR(IF(D25="","",INDEX(Tabla_Completa,MATCH(D25,Materiales,0),6)),"") | S25: =IFERROR(IF(Q25="Unidad","1",(Q25*$K$2)),"") -> 0 | W25: =IFERROR(IF(D25="","",INDEX(Tabla_Completa,MATCH(Solicitar!D25,Materiales,0),7)*S25),"")
O26: =IFERROR(IF(D26="","",INDEX(Tabla_Completa,MATCH(D26,Materiales,0),6)),"") | S26: =IFERROR(IF(Q26="Unidad","1",(Q26*$K$2)),"") -> 0 | W26: =IFERROR(IF(D26="","",INDEX(Tabla_Completa,MATCH(Solicitar!D26,Materiales,0),7)*S26),"")
O27: =IFERROR(IF(D27="","",INDEX(Tabla_Completa,MATCH(D27,Materiales,0),6)),"") | S27: =IFERROR(IF(Q27="Unidad","1",(Q27*$K$2)),"") -> 0 | W27: =IFERROR(IF(D27="","",INDEX(Tabla_Completa,MATCH(Solicitar!D27,Materiales,0),7)*S27),"")
O28: =IFERROR(IF(D28="","",INDEX(Tabla_Completa,MATCH(D28,Materiales,0),6)),"") | S28: =IFERROR(IF(Q28="Unidad","1",(Q28*$K$2)),"") -> 0 | W28: =IFERROR(IF(D28="","",INDEX(Tabla_Completa,MATCH(Solicitar!D28,Materiales,0),7)*S28),"")
A36: Recomendación:
A37: Insertar Imagen: en la ruta: Insertar/Ilustraciones/Imágenes/en este dispositivo
A41: Instrucciones Generales | N41: ADHESIVOS_Solventes | R41: Todo lo relacionado con adhesivos, incluido los solventes
A42: Los campos en color naranja son obligatorios, se deben registrar | N42: SECUNDARIO | R42: Todos los insumos que hacen parte del producto, en un nivel secundario, o que van en la parte interna de los productos. Ejm Cordones
A43: Los campos de este color en la parte de debajo o a un lado significa que tiene una lista desplegable | N43: CUERO | R43: Solo insumos bajo esta categoría
A44: Los campos en color gris oscuro y claro,son campos que no permiten edición( estan Bloqueados) | N44: HERRAJES | R44: Todos los insumos que cumplen esta condición
A45: Para ingresar la fecha, solo digite asi: tecla CTRL + tecla de punto y coma(;) | N45: HERRAMIENTAS | R45: Todos los elementos necesarios para desarrollar el proceso, estos no deben hacer parte del costo
A46: Leer cada una de las casillas con notas, como ayuda para el correcto llenado de datos | N46: INSUMOS_COMPlementarios | R46: Todos los insumos necesarios en elproceso del producto pero que no quedan dentro del producto ( ejm Agujas)
N47: PAPELERIA_P | R47: Todos los elementos que cumplen esta condición
N48: SiNTETICOS_TEXTILES | R48: Todos los insumos utilizados altenativos al cuero o forro
N49: SUELAS | R49: Todos los insumos que cumplen esta condición

Sheet BD
Z1: Bede
E3: =SUM(Total_AdhySol,Total_SECUNDARIO_MEDULAR,Total_Cuero,Total_Herrajes,Total_Sint_y_Tex,Total_Herramientas,Total_Ins_Compl) -> 660
A6: Totales | B6: =SUBTOTAL(3,(BD!$B$8:$B$18)) -> 11 | H6: Magnitudes para calculo minimo
A7: Item | B7: Material | C7: Categoría | D7: Unidad de Compra Almacen | E7: Precio Unidad de Compra ( $) | F7: Unidad Despacho Almacen | G7: Valor /U Despacho en Almacen | H7: Magnitud 1 en U | I7: Magnitud 2 en U | J7: Columna1 | K7: Columna2
A8: 1 | B8: ADHESIVO PU | C8: ADHESIVOS_Solventes | D8: gal | E8: 74650 | F8: ml | G8: =IF(BD!$E8="","",(E8/(H8*I8))) -> 19.722589 | H8: 3785 | I8: 1
A9: =A8+1 -> 2 | B9: AQUAPREN CALZADO Y MARROQUINERÍA SPRAY | C9: ADHESIVOS_Solventes | D9: gal | E9: 231671.5 | F9: ml | G9: =IF(BD!$E9="","",(E9/(H9*I9))) -> 61.207794 | H9: 3785 | I9: 1
A10: =A9+1 -> 3 | B10: AQUAPREN GUARNECIDA | C10: ADHESIVOS_Solventes | D10: gal | E10: 231671.5 | F10: ml | G10: =IF(BD!$E10="","",(E10/(H10*I10))) -> 61.207794 | H10: 3785 | I10: 1
A11: =A10+1 -> 4 | B11: CARDA RAPIDO | C11: ADHESIVOS_Solventes | D11: gal | E11: 78666.625 | F11: ml | G11: =IF(BD!$E11="","",(E11/(H11*I11))) -> 20.783785 | H11: 3785 | I11: 1
A12: =A11+1 -> 5 | B12: DILUSOR DE PINTURA 2-THIN | C12: ADHESIVOS_Solventes | D12: U | E12: 72665 | F12: U | G12: =IF(BD!$E12="","",(E12/(H12*I12))) -> 72665 | H12: 1 | I12: 1
A13: =A12+1 -> 6 | B13: HALOGENANTE | C13: ADHESIVOS_Solventes | D13: gal | E13: 59690.625 | F13: ml | G13: =IF(BD!$E13="","",(E13/(H13*I13))) -> 15.77031 | H13: 3785 | I13: 1
A14: =A13+1 -> 7 | B14: LIMPIADOR DE SUELAS | C14: ADHESIVOS_Solventes | D14: gal | E14: 50200 | F14: ml | G14: =IF(BD!$E14="","",(E14/(H14*I14))) -> 13.26288 | H14: 3785 | I14: 1
A15: =A14+1 -> 8 | B15: PEGANTE CEMENTO DE CONTACTO BASE CLOROPRENO | C15: ADHESIVOS_Solventes | D15: gal | E15: 66108 | F15: ml | G15: =IF(BD!$E15="","",(E15/(H15*I15))) -> 17.465786 | H15: 3785 | I15: 1
A16: =A15+1 -> 9 | B16: PRIMER PU | C16: ADHESIVOS_Solventes | D16: gal | E16: 61960 | F16: ml | G16: =IF(BD!$E16="","",(E16/(H16*I16))) -> 16.369881 | H16: 3785 | I16: 1
A17: =A16+1 -> 10 | B17: SOLUCIÓN DE CAUCHO | C17: ADHESIVOS_Solventes | D17: gal | E17: 28400 | F17: ml | G17: =IF(BD!$E17="","",(E17/(H17*I17))) -> 7.5033025 | H17: 3785 | I17: 1
A18: =A17+1 -> 11 | B18: THINNER | C18: ADHESIVOS_Solventes | D18: gal | E18: 36816 | F18: gal | G18: =IF(BD!$E18="","",(E18/(H18*I18))) -> 36816 | H18: 1 | I18: 1
B55: Insertar Filas!!
B100: Insertar Filas!!
A103: Totales | B103: =SUBTOTAL(3,(B105:B218)) -> 114
A104: Item | B104: Material | C104: Categoría | D104: Unidad de Compra Almacen | E104: Precio Unidad de Compra ( $) | F104: Unidad Despacho Almacen | G104: Valor /U Despacho en Almacen | H104: Magnitud 1 en U | I104: Magnitud 2 en U | J104: Columna1 | K104: Columna2
A105: 1 | B105: CAMBRIÓN | C105: SECUNDARIO | D105: Par | E105: 760 | F105: Par | G105: =IF(BD!$E105="","",(E105/(H105*I105))) -> 760 | H105: 1 | I105: 1
A106: 2 | B106: CAUCHO LATEX | C106: SECUNDARIO | D106: Lámina | E106: 45667 | F106: Lámina | G106: =IF(BD!$E106="","",(E106/(H106*I106))) -> 45667 | H106: 1 | I106: 1
A107: 3 | B107: CINTA FALLA _RIBETE 18 mm CON APRESTO #3 | C107: SECUNDARIO | D107: Rollo | E107: 41000 | F107: m | G107: =IF(BD!$E107="","",(E107/(H107*I107))) -> 410 | H107: 100 | I107: 1
A108: 4 | B108: CINTA FALLA _RIBETE 24 mm CON APRESTO #5 | C108: SECUNDARIO | D108: Rollo | E108: 58500 | F108: m | G108: =IF(BD!$E108="","",(E108/(H108*I108))) -> 585 | H108: 100 | I108: 1
A109: 5 | B109: COMFORTEX CALIBRE 1.5mm. | C109: SECUNDARIO | D109: Lámina | E109: 17830 | F109: cm2 | G109: =IF(BD!$E109="","",(E109/(H109*I109))) -> 1.2735714 | H109: 140 | I109: 100
A110: 42 | B110: Cordon ENCERADO NEGRO 110cm | C110: SECUNDARIO | D110: Par | E110: 639 | F110: Par | G110: =IF(BD!$E110="","",(E110/(H110*I110))) -> 639 | H110: 1 | I110: 1
A111: 43 | B111: CORDON ENCERADO NEGRO LARGO | C111: SECUNDARIO | D111: Par | E111: 639 | F111: Par | G111: =IF(BD!$E111="","",(E111/(H111*I111))) -> 639 | H111: 1 | I111: 1
A112: 44 | B112: CORDON ENCERADO PLANO CAFE | C112: SECUNDARIO | D112: Par | E112: 639 | F112: Par | G112: =IF(BD!$E112="","",(E112/(H112*I112))) -> 639 | H112: 1 | I112: 1
A113: 45 | B113: CORDON ENCERADO PLANO NEGRO | C113: SECUNDARIO | D113: Par | E113: 639 | F113: Par | G113: =IF(BD!$E113="","",(E113/(H113*I113))) -> 639 | H113: 1 | I113: 1
A114: 46 | B114: CORDON ENCERADO REDODNDO CAFE | C114: SECUNDARIO | D114: Par | E114: 639 | F114: Par | G114: =IF(BD!$E114="","",(E114/(H114*I114))) -> 639 | H114: 1 | I114: 1
A115: 47 | B115: CORDON NEGRO PLANO | C115: SECUNDARIO | D115: Par | E115: 639 | F115: Par | G115: =IF(BD!$E115="","",(E115/(H115*I115))) -> 639 | H115: 1 | I115: 1
A116: 48 | B116: CORDON NEGRO REDONDO | C116: SECUNDARIO | D116: Par | E116: 639 | F116: Par | G116: =IF(BD!$E116="","",(E116/(H116*I116))) -> 639 | H116: 1 | I116: 1
... A218: 128 | B218: YUMBOLON 4mm (CM²) | C218: SECUNDARIO | D218: m | E218: 10780 | F218: cm2 | G218: =IF(BD!$E218="","",(E218/(H218*I218))) -> 0.77 | H218: 140 | I218: 100
B398: Insertar Filas!!
A400: Totales | B400: =SUBTOTAL(3,(B402:B424)) -> 23
A401: Item | B401: Material | C401: Categoría | D401: Unidad de Compra Almacen | E401: Precio Unidad de Compra ( $) | F401: Unidad Despacho Almacen | G401: Valor /U Despacho en Almacen | H401: Magnitud 1 en U | I401: Magnitud 2 en U | J401: Columna1 | K401: Columna2
A402: 1 | B402: CARNAZA | C402: CUERO | D402: dm2 | E402: 380 | F402: dm2 | G402: =IF(BD!$E402="","",(E402/(H402*I402))) -> 380 | H402: 1 | I402: 1
A403: =A402+1 -> 2 | B403: CONFECCION | C403: CUERO | D403: dm2 | E403: 848.47 | F403: dm2 | G403: =IF(BD!$E404="","",(E403/(H403*I403))) -> 848.47 | H403: 1 | I403: 1
A404: =A403+1 -> 3 | B404: CUERO ARIZONA | C404: CUERO | D404: dm2 | E404: 815 | F404: dm2 | G404: =IF(BD!$E406="","",(E404/(H404*I404))) -> 815 | H404: 1 | I404: 1
A405: =A404+1 -> 4 | B405: CUERO CROSTA | C405: CUERO | D405: dm2 | E405: 623.66667 | F405: dm2 | G405: =IF(BD!$E407="","",(E405/(H405*I405))) -> 623.66667 | H405: 1 | I405: 1
A406: =A405+1 -> 5 | B406: CUERO CRUST | C406: CUERO | D406: dm2 | E406: 698.53 | F406: dm2 | G406: =IF(BD!$E405="","",(E406/(H406*I406))) -> 698.53 | H406: 1 | I406: 1
...

Sheet Listas
G1: Observaciones | I1: Categorias | V1: Lis
A2: Nombre de la Unidades | B2: Simbololo de la Unidad | G2: Restar_Pedido | I2: ADHESIVOS_Solventes
A3: Caja | B3: Caja | G3: Amarillo | I3: CUERO
A4: centimetros | B4: cm | G4: Azul | I4: HERRAJES
A5: centimetros cuadrados | B5: cm2 | G5: Blanco | I5: HERRAMIENTAS_
A6: Cono | B6: Cono | G6: Café | I6: INSUMOS_COMPL_
A7: decimetros | B7: dm | G7: Colores Surtidos | I7: SECUNDARIO
A8: decimetros Cuadrados | B8: dm2 | G8: Colores Varios | I8: SiNTETICOS_TEXTILES
A9: Frasco | B9: F | G9: Negro | I9: SUELAS
A10: Galon | B10: gal | G10: Rojo | I10: QUÍMICOS
A11: Garrafa | B11: gf | G11: Verde
A12: gramos | B12: g
A13: Hoja | B13: Hoja
A14: kilogramo | B14: kg
A15: kit | B15: kit
A16: Lamina | B16: Lámina
A17: Libra | B17: lb
A18: Litro | B18: l
A19: metros | B19: m
A20: miligramos | B20: mg
A21: mililitro | B21: ml
A22: Ovillo | B22: Ovillo
A23: Paquetre | B23: paq
... A28: Unidad | B28: U
