Workbook
Name broche: INVENTARIO!$B$3:$C$145
Name COL: #REF!
Name COMPRA: INVENTARIO!$C$3:$C$145
Name consumo: #REF!
Name INVENTARIO: INVENTARIO!$A$3:$B$145
Name listo: INVENTARIO!$A$3:$A$147
Name MATERIAL: #REF!
Name materiale: #REF!
Name materiales: consumos!$A$34:$A$58
Name materiales: consumos!$A$35:$A$58
Name matriales: consumos!$A$34
Name medidas: lista!$B$2:$B$17
Name metro: lista!$E$2:$E$19
Name NO: #REF!
Name proveedores: lista!$D$2:$D$19
Name REFF: #REF!
Name total: #REF!
Name Z_0F6C7FCE_20BD_4B57_B04C_CA521EC9CEDE_.wvu.Cols: #REF!
Name Z_0F6C7FCE_20BD_4B57_B04C_CA521EC9CEDE_.wvu.Rows: consumos!$6:$6

Sheet consumos
A1: FICHA PARA EL CONSUMO DE MATERIALES DE CALZADO Y MARROQUINERIA
A2: DOCENTE ENCARGADO | D2: MAYBELLINE ARISTIZÁBAL | F2: CURSO/TECNICO | I2: 1 | J2: COSTO POR PAR/PRODUCTO
A3: NOMBRE DEL PRODUCTO | D3: MARROQUINERIA 3 | F3: DISEÑO | J3: =SUM(G8:G32) -> 25650
A4: FECHA DE ELABORACION DEL PRODUCTO | E4: NUMERO DE CEDULA | F4: NUMERO DE FICHA | G4: NUMERO DE FICHA | I4: 1 | J4: CANTIDAD A PRODUCIR
A5: FECHA ENTREGA DEL PRODUCTO | D5: 44640 | E5: 1128404319 | F5: 2472805 | J5: 12
A7: MATERIALES E INSUMOS. | B7: VALOR | C7: MEDIDA | D7: COLOR O REFERENCIA. | E7: CONSUMO POR PRODUCTO | F7: VALOR UNIDAD DE CONSUMO | G7: COSTO | H7: COSTO TOTAL
A8: Cuero Napa Variada (Dm2) | B8: =VLOOKUP(A8,INVENTARIO,2,FALSE) -> 488 | C8: =VLOOKUP(B8,broche,2,FALSE) -> 1 | D8: 0 | E8: 24 | F8: =F34/G34 -> 488 | G8: =E8*F8*$I$2 -> 11712 | H8: =H34*F8*E8 -> 140544
A9: Seda 30-100 Colores (cm²) | B9: =VLOOKUP(A9,INVENTARIO,2,FALSE) -> 0.5 | C9: =VLOOKUP(B9,broche,2,FALSE) -> 1 | D9: 0 | E9: 7000 | F9: =F35/G35 -> 0.5 | G9: =E9*F9*$I$2 -> 3500 | H9: =H35*F9*E9 -> 42000
A10: Cremallera Nylon #6(cm) | B10: =VLOOKUP(A10,INVENTARIO,2,FALSE) -> 6 | C10: =VLOOKUP(B10,broche,2,FALSE) -> 1 | D10: 0 | E10: 100 | F10: =F36/G36 -> 6 | G10: =E10*F10*$I$2 -> 600 | H10: =H36*F10*E10 -> 7200
A11: llaves #6 Nq de lujo | B11: =VLOOKUP(A11,INVENTARIO,2,FALSE) -> 300 | C11: =VLOOKUP(B11,broche,2,FALSE) -> 1 | D11: 0 | E11: 3 | F11: =F37/G37 -> 300 | G11: =E11*F11*$I$2 -> 900 | H11: =H37*F11*E11 -> 10800
A12: Cremallera Nylon #3(cm) | B12: =VLOOKUP(A12,INVENTARIO,2,FALSE) -> 3.4 | C12: =VLOOKUP(B12,broche,2,FALSE) -> 1 | D12: 0 | E12: 20 | F12: =F38/G38 -> 3.4 | G12: =E12*F12*$I$2 -> 68 | H12: =H38*F12*E12 -> 816
A13: llaves #3 Nq Sencillas | B13: =VLOOKUP(A13,INVENTARIO,2,FALSE) -> 100 | C13: =VLOOKUP(B13,broche,2,FALSE) -> 1 | D13: 0 | E13: 1 | F13: =F39/G39 -> 100 | G13: =E13*F13*$I$2 -> 100 | H13: =H39*F13*E13 -> 1200
A14: Lambrilla de 3mm (cm²) | B14: =VLOOKUP(A14,INVENTARIO,2,FALSE) -> 0.25 | C14: =VLOOKUP(B14,broche,2,FALSE) -> 1 | E14: 7000 | F14: =F40/G40 -> 0.25 | G14: =E14*F14*$I$2 -> 1750 | H14: =H40*F14*E14 -> 21000
A15: Plantitex (cm²) | B15: =VLOOKUP(A15,INVENTARIO,2,FALSE) -> 0.42 | C15: =VLOOKUP(B15,broche,2,FALSE) -> 1 | D15: 0 | E15: 1200 | F15: =F41/G41 -> 0.42 | G15: =E15*F15*$I$2 -> 504 | H15: =H41*F15*E15 -> 6048
A16: hebilla 1" niquel | B16: =VLOOKUP(A16,INVENTARIO,2,FALSE) -> 928 | C16: =VLOOKUP(B16,broche,2,FALSE) -> 1 | D16: 0 | E16: 2 | F16: =F42/G42 -> 928 | G16: =E16*F16*$I$2 -> 1856 | H16: =H42*F16*E16 -> 22272
A17: Lona Sintetica Colores (cm²) | B17: =VLOOKUP(A17,INVENTARIO,2,FALSE) -> 0.66 | C17: =VLOOKUP(B17,broche,2,FALSE) -> 1 | D17: 0 | E17: 7000 | F17: =F43/G43 -> 0.66 | G17: =E17*F17*$I$2 -> 4620 | H17: =H43*F17*E17 -> 55440
A18: Cinta Falla de 20mm (Cm) | B18: =VLOOKUP(A18,INVENTARIO,2,FALSE) -> 0.2 | C18: =VLOOKUP(B18,broche,2,FALSE) -> 1 | D18: 0 | E18: 200 | F18: =F44/G44 -> 0.2 | G18: =E18*F18*$I$2 -> 40 | H18: =H44*F18*E18 -> 480
B19: =VLOOKUP(A19,INVENTARIO,2,FALSE) -> 0 | C19: =VLOOKUP(B19,broche,2,FALSE) -> 0 | D19: 0 | E19: 0 | F19: =F45/G45 -> 0 | G19: =E19*F19*$I$2 -> 0 | H19: =H45*F19*E19 -> 0
A20: 0 | B20: =VLOOKUP(A20,INVENTARIO,2,FALSE) -> 0 | C20: =VLOOKUP(B20,broche,2,FALSE) -> 0 | D20: 0 | E20: 0 | F20: =F46/G46 -> 0 | G20: =E20*F20*$I$2 -> 0 | H20: =H46*F20*E20 -> 0
A21: 0 | B21: =VLOOKUP(A21,INVENTARIO,2,FALSE) -> 0 | C21: =VLOOKUP(B21,broche,2,FALSE) -> 0 | D21: 0 | E21: 0 | F21: =F47/G47 -> 0 | G21: =E21*F21*$I$2 -> 0 | H21: =H47*F21*E21 -> 0
A22: 0 | B22: 0.5 | C22: =VLOOKUP(B22,broche,2,FALSE) -> 1 | D22: 0 | E22: 0 | F22: =F48/G48 -> 0.5 | G22: =E22*F22*$I$2 -> 0 | H22: =H48*F22*E22 -> 0
A23: 0 | B23: =VLOOKUP(A23,INVENTARIO,2,FALSE) -> 0 | C23: =VLOOKUP(B23,broche,2,FALSE) -> 0 | D23: 0 | E23: 0 | F23: =F49/G49 -> 0 | G23: =E23*F23*$I$2 -> 0 | H23: =H49*F23*E23 -> 0
A24: 0 | B24: =VLOOKUP(A24,INVENTARIO,2,FALSE) -> 0 | C24: =VLOOKUP(B24,broche,2,FALSE) -> 0 | D24: 0 | E24: 0 | F24: =F50/G50 -> 0 | G24: =E24*F24*$I$2 -> 0 | H24: =H50*F24*E24 -> 0
A25: 0 | B25: =VLOOKUP(A25,INVENTARIO,2,FALSE) -> 0 | C25: =VLOOKUP(B25,broche,2,FALSE) -> 0 | D25: 0 | E25: 0 | F25: =F51/G51 -> 0 | G25: =E25*F25*$I$2 -> 0 | H25: =H51*F25*E25 -> 0 | J25: VALOR DEL PRODUCTO FINAL | L25: =J3*110% -> 28215
A26: 0 | B26: =VLOOKUP(A26,INVENTARIO,2,FALSE) -> 0 | C26: =VLOOKUP(B26,broche,2,FALSE) -> 0 | D26: 0 | E26: 0 | F26: =F52/G52 -> 0 | G26: =E26*F26*$I$2 -> 0 | H26: =H52*F26*E26 -> 0
A27: 0 | B27: =VLOOKUP(A27,INVENTARIO,2,FALSE) -> 0 | C27: =VLOOKUP(B27,broche,2,FALSE) -> 0 | D27: 0 | E27: 0 | F27: =F53/G53 -> 0 | G27: =E27*F27*$I$2 -> 0 | H27: =H53*F27*E27 -> 0
A28: 0 | B28: =VLOOKUP(A28,INVENTARIO,2,FALSE) -> 0 | C28: =VLOOKUP(B28,broche,2,FALSE) -> 0 | D28: 0 | E28: 0 | F28: =F54/G54 -> 0 | G28: =E28*F28*$I$2 -> 0 | H28: =H54*F28*E28 -> 0 | J28: VALOR DE LA PRODUCCION | L28: =L25*J5 -> 338580
A29: 0 | B29: =VLOOKUP(A29,INVENTARIO,2,FALSE) -> 0 | C29: =VLOOKUP(B29,broche,2,FALSE) -> 0 | D29: 0 | E29: 0 | F29: =F55/G55 -> 0 | G29: =E29*F29*$I$2 -> 0 | H29: =H55*F29*E29 -> 0
A30: 0 | B30: =VLOOKUP(A30,INVENTARIO,2,FALSE) -> 0 | C30: =VLOOKUP(B30,broche,2,FALSE) -> 0 | D30: 0 | E30: 0 | F30: =F56/G56 -> 0 | G30: =E30*F30*$I$2 -> 0 | H30: =H56*F30*E30 -> 0
A31: 0 | B31: =VLOOKUP(A31,INVENTARIO,2,FALSE) -> 0 | C31: =VLOOKUP(B31,broche,2,FALSE) -> 0 | D31: 0 | E31: 0 | F31: =F57/G57 -> 0 | G31: =E31*F31*$I$2 -> 0 | H31: =H57*F31*E31 -> 0
A32: 0 | B32: =VLOOKUP(A32,INVENTARIO,2,FALSE) -> 0 | C32: =VLOOKUP(B32,broche,2,FALSE) -> 0 | D32: 0 | E32: 0 | F32: =F58/G58 -> 0 | G32: =E32*F32*$I$2 -> 0 | H32: =H58*F32*E32 -> 0
A34: =A8 -> Cuero Napa Variada (Dm2) | D34: =IF(D8<1,0,D8) -> 0 | E34: =IF(C8*B8<1,0,C8) -> 1 | F34: =B8 -> 488 | G34: =IF(E34<1,(1),E34) -> 1 | H34: =J5 -> 12 | I34: =G8/G34 -> 11712
A35: =A9 -> Seda 30-100 Colores (cm²) | D35: =IF(D9<1,0,D9) -> 0 | E35: =IF(C9*B9<1,0,C9) -> 0 | F35: =B9 -> 0.5 | G35: =IF(E35<1,(1),E35) -> 1 | H35: =J5 -> 12 | I35: =G9/G35 -> 3500
A36: =A10 -> Cremallera Nylon #6(cm) | D36: =IF(D10<1,0,D10) -> 0 | E36: =IF(C10*B10<1,0,C10) -> 1 | F36: =B10 -> 6 | G36: =IF(E36<1,(1),E36) -> 1 | H36: =J5 -> 12 | I36: =G10/G36 -> 600
A37: =A11 -> llaves #6 Nq de lujo | D37: =IF(D11<1,0,D11) -> 0 | E37: =IF(C11*B11<1,0,C11) -> 1 | F37: =B11 -> 300 | G37: =IF(E37<1,(1),E37) -> 1 | H37: =J5 -> 12 | I37: =G11/G37 -> 900
A38: =A12 -> Cremallera Nylon #3(cm) | D38: =IF(D12<1,0,D12) -> 0 | E38: =IF(C12*B12<1,0,C12) -> 1 | F38: =B12 -> 3.4 | G38: =IF(E38<1,(1),E38) -> 1 | H38: =J5 -> 12 | I38: =G12/G38 -> 68
A39: =A13 -> llaves #3 Nq Sencillas | D39: =IF(D13<1,0,D13) -> 0 | E39: =IF(C13*B13<1,0,C13) -> 1 | F39: =B13 -> 100 | G39: =IF(E39<1,(1),E39) -> 1 | H39: =J5 -> 12 | I39: =G13/G39 -> 100
A40: =A14 -> Lambrilla de 3mm (cm²) | D40: =IF(D14<1,0,D14) -> 0 | E40: =IF(C14*B14<1,0,C14) -> 0 | F40: =B14 -> 0.25 | G40: =IF(E40<1,(1),E40) -> 1 | H40: =J5 -> 12 | I40: =G14/G40 -> 1750
A41: =A15 -> Plantitex (cm²) | D41: =IF(D15<1,0,D15) -> 0 | E41: =IF(C15*B15<1,0,C15) -> 0 | F41: =B15 -> 0.42 | G41: =IF(E41<1,(1),E41) -> 1 | H41: =J5 -> 12 | I41: =G15/G41 -> 504
A42: =A16 -> hebilla 1" niquel | D42: =IF(D16<1,0,D16) -> 0 | E42: =IF(C16*B16<1,0,C16) -> 1 | F42: =B16 -> 928 | G42: =IF(E42<1,(1),E42) -> 1 | H42: =J5 -> 12 | I42: =G16/G42 -> 1856
...

Sheet PEDIDO
A1: =consumos!A2 -> DOCENTE ENCARGADO | B1: =consumos!A3 -> NOMBRE DEL PRODUCTO | C1: =consumos!G4 -> NUMERO DE FICHA | D1: =consumos!F2 -> CURSO/TECNICO | H1: ENTREGAS PARCIALES
A2: =consumos!D2 -> MAYBELLINE ARISTIZÁBAL | B2: =consumos!D3 -> MARROQUINERIA 3 | C2: =consumos!F5 -> 2472805 | D2: =consumos!F3 -> DISEÑO | F2: =consumos!E5 -> 1128404319
A3: MATERIAL | B3: REFERENCIA O COLOR | C3: POR CADA PRODUCTO | D3: REQUISICION DE MATERIALES DM, UD Y CM | E3: CM LINEAL | F3: VALOR | H3: ENTREGADO | J3: PENDIENTE POR ENTREGAR | K3: 1 | L3: 2 | M3: 3 | N3: 4 | O3: 5 | P3: 6 | Q3: 7 | R3: 8 | S3: 9 | T3: 10 | U3: INSUMOS SIN COSTO | V3: CANTIDAD | W3: PENDIENTE POR ENTREGAR | X3: ENTREGADO
A4: =consumos!A34 -> Cuero Napa Variada (Dm2) | B4: =consumos!D8 -> 0 | C4: =consumos!E8 -> 24 | D4: =consumos!E8*consumos!J5 -> 288 | E4: =MEDIDAS!C21 -> 0.16551724 | F4: =consumos!H8 -> 140544 | H4: =IF(I4>D4,(FALSE),I4) -> FALSE | I4: =(K4+L4+M4+N4+O4+P4+Q4+R4+S4+T4) -> 314 | J4: =D4-(K4+L4+M4+N4+O4+P4+Q4+R4+S4+T4) -> -26 | K4: 201 | L4: 113 | M4: 0 | N4: 0 | O4: 0 | P4: 0 | Q4: 0 | R4: 0 | S4: 0 | T4: 0 | U4: =consumos!A77 -> Aguja Corta Cabo Delgada (unidad) | V4: =IF(consumos!D77<0,(1),consumos!D77) -> 0 | W4: =V4-X4 -> 0 | X4: 0
A5: =consumos!A35 -> Seda 30-100 Colores (cm²) | B5: =consumos!D9 -> 0 | C5: =consumos!E9 -> 7000 | D5: =consumos!E9*consumos!J5 -> 84000 | E5: =MEDIDAS!C22 -> 48.275862 | F5: =consumos!H9 -> 42000 | H5: =IF(I5>D5,(FALSE),I5) -> 84000 | I5: =(K5+L5+M5+N5+O5+P5+Q5+R5+S5+T5) -> 84000 | J5: =D5-(K5+L5+M5+N5+O5+P5+Q5+R5+S5+T5) -> 0 | K5: 84000 | L5: 0 | M5: 0 | N5: 0 | O5: 0 | P5: 0 | Q5: 0 | R5: 0 | S5: 0 | T5: 0 | U5: =consumos!A78 -> Aguja Corta Cabo Grueso (unidad) | V5: =IF(consumos!D78<0,(1),consumos!D78) -> 0 | W5: =V5-X5 -> 0 | X5: 0
A6: =consumos!A36 -> Cremallera Nylon #6(cm) | B6: =consumos!D10 -> 0 | C6: =consumos!E10 -> 100 | D6: =consumos!E10*consumos!J5 -> 1200 | E6: =MEDIDAS!C23 -> 0.68965517 | F6: =consumos!H10 -> 7200 | H6: =IF(I6>D6,(FALSE),I6) -> 1200 | I6: =(K6+L6+M6+N6+O6+P6+Q6+R6+S6+T6) -> 1200 | J6: =D6-(K6+L6+M6+N6+O6+P6+Q6+R6+S6+T6) -> 0 | K6: 1200 | L6: 0 | M6: 0 | N6: 0 | O6: 0 | P6: 0 | Q6: 0 | R6: 0 | S6: 0 | T6: 0 | U6: =consumos!A79 -> Bolsa Plastica Cargadera ( unidad) | V6: =IF(consumos!D79<0,(1),consumos!D79) -> 0 | W6: =V6-X6 -> 0 | X6: 0
A7: =consumos!A37 -> llaves #6 Nq de lujo | B7: =consumos!D11 -> 0 | C7: =consumos!E11 -> 3 | D7: =consumos!E11*consumos!J5 -> 36 | E7: =MEDIDAS!C24 -> 0.020689655 | F7: =consumos!H11 -> 10800 | H7: =IF(I7>D7,(FALSE),I7) -> 24 | I7: =(K7+L7+M7+N7+O7+P7+Q7+R7+S7+T7) -> 24 | J7: =D7-(K7+L7+M7+N7+O7+P7+Q7+R7+S7+T7) -> 12 | K7: 24 | L7: 0 | M7: 0 | N7: 0 | O7: 0 | P7: 0 | Q7: 0 | R7: 0 | S7: 0 | T7: 0 | U7: =consumos!A80 -> Bolsa plastica de 12*14 ( unidad) | V7: =IF(consumos!D80<0,(1),consumos!D80) -> 0 | W7: =V7-X7 -> 0 | X7: 0
A8: =consumos!A38 -> Cremallera Nylon #3(cm) | B8: =consumos!D12 -> 0 | C8: =consumos!E12 -> 20 | D8: =consumos!E12*consumos!J5 -> 240 | E8: =MEDIDAS!C25 -> 0.13793103 | F8: =consumos!H12 -> 816 | H8: =IF(I8>D8,(FALSE),I8) -> 240 | I8: =(K8+L8+M8+N8+O8+P8+Q8+R8+S8+T8) -> 240 | J8: =D8-(K8+L8+M8+N8+O8+P8+Q8+R8+S8+T8) -> 0 | K8: 240 | L8: 0 | M8: 0 | N8: 0 | O8: 0 | P8: 0 | Q8: 0 | R8: 0 | S8: 0 | T8: 0 | U8: =consumos!A81 -> Bolsa Plastica de 15*22 ( unidad) | V8: =IF(consumos!D81<0,(1),consumos!D81) -> 0 | W8: =V8-X8 -> 0 | X8: 0
A9: =consumos!A39 -> llaves #3 Nq Sencillas | B9: =consumos!D13 -> 0 | C9: =consumos!E13 -> 1 | D9: =consumos!E13*consumos!J5 -> 12 | E9: =MEDIDAS!C26 -> 0.0068965517 | F9: =consumos!H13 -> 1200 | H9: =IF(I9>D9,(FALSE),I9) -> 12 | I9: =(K9+L9+M9+N9+O9+P9+Q9+R9+S9+T9) -> 12 | J9: =D9-(K9+L9+M9+N9+O9+P9+Q9+R9+S9+T9) -> 0 | K9: 12 | L9: 0 | M9: 0 | N9: 0 | O9: 0 | P9: 0 | Q9: 0 | R9: 0 | S9: 0 | T9: 0 | U9: =consumos!A82 -> Cambre de 100gr (cm²) | V9: =IF(consumos!D82<0,(1),consumos!D82) -> 56000 | W9: =V9-X9 -> 56000
A10: =consumos!A40 -> Lambrilla de 3mm (cm²) | B10: =consumos!D14 -> 0 | C10: =consumos!E14 -> 7000 | D10: =consumos!E14*consumos!J5 -> 84000 | E10: =MEDIDAS!C27 -> 48.275862 | F10: =consumos!H14 -> 21000 | H10: =IF(I10>D10,(FALSE),I10) -> 28000 | I10: =(K10+L10+M10+N10+O10+P10+Q10+R10+S10+T10) -> 28000 | J10: =D10-(K10+L10+M10+N10+O10+P10+Q10+R10+S10+T10) -> 56000 | K10: 28000 | L10: 0 | M10: 0 | N10: 0 | O10: 0 | P10: 0 | Q10: 0 | R10: 0 | S10: 0 | T10: 0 | U10: =consumos!A83 -> Carton Corrugado (pliego) | V10: =IF(consumos!D83<0,(1),consumos!D83) -> 0 | W10: =V10-X10 -> 0 | X10: 0
A11: =consumos!A41 -> Plantitex (cm²) | B11: =consumos!D15 -> 0 | C11: =consumos!E15 -> 1200 | D11: =consumos!E15*consumos!J5 -> 14400 | E11: =MEDIDAS!C28 -> 8.2758621 | F11: =consumos!H15 -> 6048 | H11: =IF(I11>D11,(FALSE),I11) -> 0 | I11: =(K11+L11+M11+N11+O11+P11+Q11+R11+S11+T11) -> 0 | J11: =D11-(K11+L11+M11+N11+O11+P11+Q11+R11+S11+T11) -> 14400 | K11: 0 | L11: 0 | M11: 0 | N11: 0 | O11: 0 | P11: 0 | Q11: 0 | R11: 0 | S11: 0 | T11: 0 | U11: =consumos!A84 -> Carton duplex (pliego) | V11: =IF(consumos!D84<0,(1),consumos!D84) -> 0 | W11: =V11-X11 -> 0 | X11: 0
A12: =consumos!A42 -> hebilla 1" niquel | B12: =consumos!D16 -> 0 | C12: =consumos!E16 -> 2 | D12: =consumos!E16*consumos!J5 -> 24 | E12: =MEDIDAS!C29 -> 0.013793103 | F12: =consumos!H16 -> 22272 | H12: =IF(I12>D12,(FALSE),I12) -> 14 | I12: =(K12+L12+M12+N12+O12+P12+Q12+R12+S12+T12) -> 14 | J12: =D12-(K12+L12+M12+N12+O12+P12+Q12+R12+S12+T12) -> 10 | K12: 14 | L12: 0 | M12: 0 | N12: 0 | O12: 0 | P12: 0 | Q12: 0 | R12: 0 | S12: 0 | T12: 0 | U12: =consumos!A85 -> Carton Paja (pliego) | V12: =IF(consumos!D85<0,(1),consumos!D85) -> 0 | W12: =V12-X12 -> 0 | X12: 0
A13: =consumos!A43 -> Lona Sintetica Colores (cm²) | B13: =consumos!D17 -> 0 | C13: =consumos!E17 -> 7000 | D13: =consumos!E17*consumos!J5 -> 84000 | E13: =MEDIDAS!C30 -> 48.275862 | F13: =consumos!H17 -> 55440 | H13: =IF(I13>D13,(FALSE),I13) -> 84000 | I13: =(K13+L13+M13+N13+O13+P13+Q13+R13+S13+T13) -> 84000 | J13: =D13-(K13+L13+M13+N13+O13+P13+Q13+R13+S13+T13) -> 0 | K13: 84000 | L13: 0 | M13: 0 | N13: 0 | O13: 0 | P13: 0 | Q13: 0 | R13: 0 | S13: 0 | T13: 0 | U13: =consumos!A86 -> Cartulina (pliego) | V13: =IF(consumos!D86<0,(1),consumos!D86) -> 10 | W13: =V13-X13 -> 10 | X13: 0
A14: =consumos!A44 -> Cinta Falla de 20mm (Cm) | B14: =consumos!D18 -> 0 | C14: =consumos!E18 -> 200 | D14: =consumos!E18*consumos!J5 -> 2400 | E14: =MEDIDAS!C31 -> 1.3793103 | F14: =consumos!H18 -> 480 | H14: =IF(I14>D14,(FALSE),I14) -> 0 | I14: =(K14+L14+M14+N14+O14+P14+Q14+R14+S14+T14) -> 0 | J14: =D14-(K14+L14+M14+N14+O14+P14+Q14+R14+S14+T14) -> 2400 | L14: 0 | M14: 0 | N14: 0 | O14: 0 | P14: 0 | Q14: 0 | R14: 0 | S14: 0 | T14: 0 | U14: =consumos!A87 -> Cinta de Enmascarar de 2" (unidad) | V14: =IF(consumos!D87<0,(1),consumos!D87) -> 0 | W14: =V14-X14 -> 0
A15: =consumos!A45 -> 0 | B15: =consumos!D19 -> 0 | C15: =consumos!E19 -> 0 | D15: =consumos!E19*consumos!J5 -> 0 | E15: =MEDIDAS!C32 -> 0 | F15: =consumos!H19 -> 0 | H15: =IF(I15>D15,(FALSE),I15) -> 0 | I15: =(K15+L15+M15+N15+O15+P15+Q15+R15+S15+T15) -> 0 | J15: =D15-(K15+L15+M15+N15+O15+P15+Q15+R15+S15+T15) -> 0 | L15: 0 | M15: 0 | N15: 0 | O15: 0 | P15: 0 | Q15: 0 | R15: 0 | S15: 0 | T15: 0 | U15: =consumos!A88 -> Cinta de trasparente (unidad) | V15: =IF(consumos!D88<0,(1),consumos!D88) -> 0 | W15: =V15-X15 -> 0 | X15: 0
A16: =consumos!A46 -> 0 | B16: =consumos!D20 -> 0 | C16: =consumos!E20 -> 0 | D16: =consumos!E20*consumos!J5 -> 0 | E16: =MEDIDAS!C33 -> 0 | F16: =consumos!H20 -> 0 | H16: =IF(I16>D16,(FALSE),I16) -> 0 | I16: =(K16+L16+M16+N16+O16+P16+Q16+R16+S16+T16) -> 0 | J16: =D16-(K16+L16+M16+N16+O16+P16+Q16+R16+S16+T16) -> 0 | K16: 0 | L16: 0 | M16: 0 | N16: 0 | O16: 0 | P16: 0 | Q16: 0 | R16: 0 | S16: 0 | T16: 0 | U16: =consumos!A89 -> Ecohalogenante para suelas | V16: =IF(consumos!D89<0,(1),consumos!D89) -> 0 | W16: =V16-X16 -> 0 | X16: 0
A17: =consumos!A47 -> 0 | B17: =consumos!D21 -> 0 | C17: =consumos!E21 -> 0 | D17: =consumos!E21*consumos!J5 -> 0 | E17: =MEDIDAS!C34 -> 0 | F17: =consumos!H21 -> 0 | H17: =IF(I17>D17,(FALSE),I17) -> 0 | I17: =(K17+L17+M17+N17+O17+P17+Q17+R17+S17+T17) -> 0 | J17: =D17-(K17+L17+M17+N17+O17+P17+Q17+R17+S17+T17) -> 0 | K17: 0 | L17: 0 | M17: 0 | N17: 0 | O17: 0 | P17: 0 | Q17: 0 | R17: 0 | S17: 0 | T17: 0 | U17: =consumos!A90 -> Ecolimpiador para suelas | V17: =IF(consumos!D90<0,(1),consumos!D90) -> 0 | W17: =V17-X17 -> 0 | X17: 0
A18: =consumos!A48 -> 0 | B18: =consumos!D22 -> 0 | C18: =consumos!E22 -> 0 | D18: =consumos!E22*consumos!J5 -> 0 | E18: =MEDIDAS!C35 -> 0 | F18: =consumos!H22 -> 0 | H18: =IF(I18>D18,(FALSE),I18) -> 0 | I18: =(K18+L18+M18+N18+O18+P18+Q18+R18+S18+T18) -> 0 | J18: =D18-(K18+L18+M18+N18+O18+P18+Q18+R18+S18+T18) -> 0 | K18: 0 | L18: 0 | M18: 0 | N18: 0 | O18: 0 | P18: 0 | Q18: 0 | R18: 0 | S18: 0 | T18: 0 | U18: =consumos!A91 -> Halogenante LH rapido ( galòn 3600 cm 3) | V18: =IF(consumos!D91<0,(1),consumos!D91) -> 0 | W18: =V18-X18 -> 0 | X18: 0
A19: =consumos!A49 -> 0 | B19: =consumos!D23 -> 0 | C19: =consumos!E23 -> 0 | D19: =consumos!E23*consumos!J5 -> 0 | E19: =MEDIDAS!C36 -> 0 | F19: =consumos!H23 -> 0 | H19: =IF(I19>D19,(FALSE),I19) -> 0 | I19: =(K19+L19+M19+N19+O19+P19+Q19+R19+S19+T19) -> 0 | J19: =D19-(K19+L19+M19+N19+O19+P19+Q19+R19+S19+T19) -> 0 | K19: 0 | L19: 0 | M19: 0 | N19: 0 | O19: 0 | P19: 0 | Q19: 0 | R19: 0 | S19: 0 | T19: 0 | U19: =consumos!A92 -> Halogenante rapido 0817 | V19: =IF(consumos!D92<0,(1),consumos!D92) -> 0 | W19: =V19-X19 -> 0 | X19: 0
A20: =consumos!A50 -> 0 | B20: =consumos!D24 -> 0 | C20: =consumos!E24 -> 0 | D20: =consumos!E24*consumos!J5 -> 0 | E20: =MEDIDAS!C37 -> 0 | F20: =consumos!H24 -> 0 | H20: =IF(I20>D20,(FALSE),I20) -> 0 | I20: =(K20+L20+M20+N20+O20+P20+Q20+R20+S20+T20) -> 0 | J20: =D20-(K20+L20+M20+N20+O20+P20+Q20+R20+S20+T20) -> 0 | K20: 0 | L20: 0 | M20: 0 | N20: 0 | O20: 0 | P20: 0 | Q20: 0 | R20: 0 | S20: 0 | T20: 0 | U20: =consumos!A93 -> Hilo Colores surtidos# 20 (cono 250 mt) | V20: =IF(consumos!D93<0,(1),consumos!D93) -> 0 | W20: =V20-X20 -> 0 | X20: 0
A21: =consumos!A51 -> 0 | B21: =consumos!D25 -> 0 | C21: =consumos!E25 -> 0 | D21: =consumos!E25*consumos!J5 -> 0 | E21: =MEDIDAS!C38 -> 0 | F21: =consumos!H25 -> 0 | H21: =IF(I21>D21,(FALSE),I21) -> 0 | I21: =(K21+L21+M21+N21+O21+P21+Q21+R21+S21+T21) -> 0 | J21: =D21-(K21+L21+M21+N21+O21+P21+Q21+R21+S21+T21) -> 0 | K21: 0 | L21: 0 | M21: 0 | N21: 0 | O21: 0 | P21: 0 | Q21: 0 | R21: 0 | S21: 0 | T21: 0 | U21: =consumos!A94 -> Hilo Colores surtidos# 40 (cono 1000 mt) | V21: =IF(consumos!D94<0,(1),consumos!D94) -> 0 | W21: =V21-X21 -> 0 | X21: 0
A22: =consumos!A52 -> 0 | B22: =consumos!D26 -> 0 | C22: =consumos!E26 -> 0 | D22: =consumos!E26*consumos!J5 -> 0 | E22: =MEDIDAS!C39 -> 0 | F22: =consumos!H26 -> 0 | H22: =IF(I22>D22,(FALSE),I22) -> 0 | I22: =(K22+L22+M22+N22+O22+P22+Q22+R22+S22+T22) -> 0 | J22: =D22-(K22+L22+M22+N22+O22+P22+Q22+R22+S22+T22) -> 0 | K22: 0 | L22: 0 | M22: 0 | N22: 0 | O22: 0 | P22: 0 | Q22: 0 | R22: 0 | S22: 0 | T22: 0 | U22: =consumos!A95 -> Hilo Colores surtidos# 60 (cono 1500 mt) | V22: =IF(consumos!D95<0,(1),consumos!D95) -> 0 | W22: =V22-X22 -> 0
A23: =consumos!A53 -> 0 | B23: =consumos!D27 -> 0 | C23: =consumos!E27 -> 0 | D23: =consumos!E27*consumos!J5 -> 0 | E23: =MEDIDAS!C40 -> 0 | F23: =consumos!H27 -> 0 | H23: =IF(I23>D23,(FALSE),I23) -> 0 | I23: =(K23+L23+M23+N23+O23+P23+Q23+R23+S23+T23) -> 0 | J23: =D23-(K23+L23+M23+N23+O23+P23+Q23+R23+S23+T23) -> 0 | K23: 0 | L23: 0 | M23: 0 | N23: 0 | O23: 0 | P23: 0 | Q23: 0 | R23: 0 | S23: 0 | T23: 0 | U23: =consumos!A96 -> Hilo Encerado cono 100 gr (metro) | V23: =IF(consumos!D96<0,(1),consumos!D96) -> 0 | W23: =V23-X23 -> 0 | X23: 0
A24: =consumos!A54 -> 0 | B24: =consumos!D28 -> 0 | C24: =consumos!E28 -> 0 | D24: =consumos!E28*consumos!J5 -> 0 | E24: =MEDIDAS!C41 -> 0 | F24: =consumos!H28 -> 0 | H24: =IF(I24>D24,(FALSE),I24) -> 0 | I24: =(K24+L24+M24+N24+O24+P24+Q24+R24+S24+T24) -> 0 | J24: =D24-(K24+L24+M24+N24+O24+P24+Q24+R24+S24+T24) -> 0 | K24: 0 | L24: 0 | M24: 0 | N24: 0 | O24: 0 | P24: 0 | Q24: 0 | R24: 0 | S24: 0 | T24: 0 | U24: =consumos!A97 -> Hilo Terlenka 2 cabos (cono 150mt) | V24: =IF(consumos!D97<0,(1),consumos!D97) -> 0 | W24: =V24-X24 -> 0 | X24: 0
A25: =consumos!A55 -> 0 | B25: =consumos!D29 -> 0 | C25: =consumos!E29 -> 0 | D25: =consumos!E29*consumos!J5 -> 0 | E25: =MEDIDAS!C42 -> 0 | F25: =consumos!H29 -> 0 | H25: =IF(I25>D25,(FALSE),I25) -> 0 | I25: =(K25+L25+M25+N25+O25+P25+Q25+R25+S25+T25) -> 0 | J25: =D25-(K25+L25+M25+N25+O25+P25+Q25+R25+S25+T25) -> 0 | K25: 0 | L25: 0 | M25: 0 | N25: 0 | O25: 0 | P25: 0 | Q25: 0 | R25: 0 | S25: 0 | T25: 0 | U25: =consumos!A98 -> Interlon (cm²) | V25: =IF(consumos!D98<0,(1),consumos!D98) -> 70000 | W25: =V25-X25 -> -70000 | X25: 140000
A26: =consumos!A56 -> 0 | B26: =consumos!D30 -> 0 | C26: =consumos!E30 -> 0 | D26: =consumos!E30*consumos!J5 -> 0 | E26: =MEDIDAS!C43 -> 0 | F26: =consumos!H30 -> 0 | H26: =IF(I26>D26,(FALSE),I26) -> 0 | I26: =(K26+L26+M26+N26+O26+P26+Q26+R26+S26+T26) -> 0 | J26: =D26-(K26+L26+M26+N26+O26+P26+Q26+R26+S26+T26) -> 0 | K26: 0 | L26: 0 | M26: 0 | N26: 0 | O26: 0 | P26: 0 | Q26: 0 | R26: 0 | S26: 0 | T26: 0 | U26: =consumos!A99 -> Lamina Zinc (unidad) | V26: =IF(consumos!D99<0,(1),consumos!D99) -> 0 | W26: =V26-X26 -> 0 | X26: 0
A27: =consumos!A57 -> 0 | B27: =consumos!D31 -> 0 | C27: =consumos!E31 -> 0 | D27: =consumos!E31*consumos!J5 -> 0 | E27: =MEDIDAS!C44 -> 0 | F27: =consumos!H31 -> 0 | H27: =IF(I27>D27,(FALSE),I27) -> 0 | I27: =(K27+L27+M27+N27+O27+P27+Q27+R27+S27+T27) -> 0 | J27: =D27-(K27+L27+M27+N27+O27+P27+Q27+R27+S27+T27) -> 0 | K27: 0 | L27: 0 | M27: 0 | N27: 0 | O27: 0 | P27: 0 | Q27: 0 | R27: 0 | S27: 0 | T27: 0 | U27: =consumos!A100 -> Lija de Agua#120 (unidad) | V27: =IF(consumos!D100<0,(1),consumos!D100) -> 0 | W27: =V27-X27 -> 0
A28: =consumos!A58 -> 0 | B28: =consumos!D32 -> 0 | C28: =consumos!E32 -> 0 | D28: =consumos!E32*consumos!J5 -> 0 | E28: =MEDIDAS!C45 -> 0 | F28: =consumos!H32 -> 0 | H28: =IF(I28>D28,(FALSE),I28) -> 0 | I28: =(K28+L28+M28+N28+O28+P28+Q28+R28+S28+T28) -> 0 | J28: =D28-(K28+L28+M28+N28+O28+P28+Q28+R28+S28+T28) -> 0 | K28: 0 | L28: 0 | M28: 0 | N28: 0 | O28: 0 | P28: 0 | Q28: 0 | R28: 0 | S28: 0 | T28: 0 | U28: =consumos!A101 -> Lija de Agua#180 (unidad) | V28: =IF(consumos!D101<0,(1),consumos!D101) -> 0 | W28: =V28-X28 -> 0 | X28: 0
A29: Elaborado por: JAIRO E GUERRERO B. Docente técnico SENA ITAGUI ANTIOQUIA 16-09-2010 VALOR TOTAL | F29: =SUM(F4:F28) -> 307800 | K29: =consumos!A62 -> OBSERVACIONES | U29: =consumos!A102 -> Lija de Agua#240 (unidad) | V29: =IF(consumos!D102<0,(1),consumos!D102) -> 0 | W29: =V29-X29 -> 0
A30: MODIFICADO POR: JAIDER ROJAS - ALMACENISTA (26-02-2017)SENA ITAGUI ANTIOQUIA | U30: =consumos!A103 -> Lija de Agua#400 (unidad) | V30: =IF(consumos!D103<0,(1),consumos!D103) -> 0 | W30: =V30-X30 -> 0 | X30: 0
K31: =consumos!A63 -> LIJA 400 8 UNIDADES | U31: =consumos!A104 -> Lija de Agua#600 (unidad) | V31: =IF(consumos!D104<0,(1),consumos!D104) -> 0 | W31: =V31-X31 -> 0 | X31: 0
K32: =consumos!A64 -> PEGAUCHO DE CONTAC TO AMARILLA | U32: =consumos!A105 -> Limpiador AT 20 ( galón 3600 cm 3) | V32: =IF(consumos!D105<0,(1),consumos!D105) -> 0 | W32: =V32-X32 -> 0 | X32: 0
K33: =consumos!A65 -> CARTULINA 10 UNIDADES | U33: =consumos!A106 -> Limpiador para acabados | V33: =IF(consumos!D106<0,(1),consumos!D106) -> 0 | W33: =V33-X33 -> 0 | X33: 0
K34: =consumos!A66 -> TINTA DE COLORES PARA CUERO Café , baigue y matanate acuoso. | U34: =consumos!A107 -> Limpiador VZ 40 ( galón 3600 cm 3) | V34: =IF(consumos!D107<0,(1),consumos!D107) -> 0 | W34: =V34-X34 -> 0 | X34: 0
K35: =consumos!A67 -> entrego hebilla 376 14 unidades, no tenemos hebilla de pulgada niquel | U35: =consumos!A108 -> Papel periodico (pliego) | V35: =IF(consumos!D108<0,(1),consumos!D108) -> 0 | W35: =V35-X35 -> 0 | X35: 0
K36: =consumos!A68 -> hilo # 40 1| | U36: =consumos!A109 -> Pegante advance o pega amarilla | V36: =IF(consumos!D109<0,(1),consumos!D109) -> 1 | W36: =V36-X36 -> 0 | X36: 1
K37: =consumos!A69 -> 0 | U37: =consumos!A110 -> Pu 419 pegante poliuretano | V37: =IF(consumos!D110<0,(1),consumos!D110) -> 0 | W37: =V37-X37 -> 0 | X37: 0
K38: =consumos!A70 -> 0 | U38: =consumos!A111 -> Pintura Acrilica X150 gr (unidad) | V38: =IF(consumos!D111<0,(1),consumos!D111) -> 0 | W38: =V38-X38 -> 0 | X38: 0
K39: =consumos!A71 -> 0 | U39: =consumos!A112 -> Primer eva plus | V39: =IF(consumos!D112<0,(1),consumos!D112) -> 0 | W39: =V39-X39 -> 0 | X39: 0
K40: =consumos!A72 -> 0 | U40: =consumos!A113 -> Primer PU 419 | V40: =IF(consumos!D113<0,(1),consumos!D113) -> 0 | W40: =V40-X40 -> 0 | X40: 0
...

Sheet lista
A1: medidas | B1: medidas | D1: proveedores | E1: metro
A2: metro | B2: METRO | D2: los angeles | E2: metro
A3: decimetro | B3: dm2 | D3: la reno | E3: dm2
A4: centimetro | B4: cm² | D4: itagui | E4: cm²
A5: gramo | B5: pie | E5: par
B6: gruesa | E6: unidad
B7: PAR | E7: gr
B8: LAMINA | E8: k
B9: UNIDAD | E9: CONO
B10: CAJA | E10: PLIEGO
B12: MILLAR
B13: GALON
A14: CONO | B14: CONO
B15: kg | D15: la global
B16: PLIEGO
B17: gr
B18: METRO
B19: HOJA

Sheet MEDIDAS
A1: MEDIDAS DE MATERIALES ANCHO EN CENTIMETROS | B1: CANTIDAD CM² | C1: CONVERSION DEL ROLLO EN CM | D1: CONVERSION DEL ROLLO EN DM | E1: CONVERSION DEL ROLLO EN M | F1: CANTIDAD DE PRODUCTOS | G1: CANTIDAD TOTAL DE MATERIAL EN M | H1: ESTA TABLA ESTA DISEÑADA PARA CONVERTIR LAS MEDIDAS DE LOS ROLLOS DE MATERIAL QUE HAY EN EL ALMACEN DE CDMC
A2: 140 | B2: 0 | C2: =B2/A2 -> 0 | D2: =C2/10 -> 0 | E2: =C2/100 -> 0 | F2: 0 | G2: =F2*E2 -> 0
A3: 150 | B3: 0 | C3: =B3/A3 -> 0 | D3: =C3/100 -> 0 | E3: =C3/100 -> 0 | F3: 0 | G3: =F3*E3 -> 0
A4: 100 | B4: 0 | C4: =B4/A4 -> 0 | D4: =C4/100 -> 0 | E4: =C4/100 -> 0 | F4: 0 | G4: =F4*E4 -> 0
A5: 50 | B5: 0 | C5: =B5/A5 -> 0 | D5: =C5/100 -> 0 | E5: =C5/100 -> 0 | F5: 0 | G5: =F5*E5 -> 0
A7: MEDIDAS DE MATERIALES ANCHO EN DECIMETROS | B7: CANTIDAD DM² | C7: CONVERSION DEL ROLLO EN DM | D7: CONVERSION DEL ROLLO EN CM | E7: CONVERSION DEL ROLLO EN M | F7: CANTIDAD DE PRODUCTOS | G7: CANTIDAD TOTAL DE MATERIAL EN M
A8: 14 | B8: 0 | C8: =B8/A8 -> 0 | D8: =C8*10 -> 0 | E8: =C8/10 -> 0 | F8: 0 | G8: =F8*E8 -> 0
A9: 15 | B9: 0 | C9: =B9/A9 -> 0 | D9: =C9*10 -> 0 | E9: =C9/10 -> 0 | F9: 0 | G9: =F9*E9 -> 0
A10: 10 | B10: 0 | C10: =B10/A10 -> 0 | D10: =C10*10 -> 0 | E10: =C10/10 -> 0 | F10: 0 | G10: =F10*E10 -> 0
A11: 5 | B11: 0 | C11: =B11/A11 -> 0 | D11: =C11*10 -> 0 | E11: =C11/10 -> 0 | F11: 0 | G11: =F11*E11 -> 0
A13: MEDIDAS DE MATERIALES ANCHO EN METROS | B13: CANTIDAD M² | C13: CONVERSION DEL ROLLO EN M | D13: CONVERSION DEL ROLLO EN CM | E13: CONVERSION DEL ROLLO EN DM | F13: CANTIDAD DE PRODUCTOS | G13: CANTIDAD TOTAL DE MATERIAL EN M
A14: 1.4 | B14: 0 | C14: =B14/A14 -> 0 | D14: =C14*100 -> 0 | E14: =C14*10 -> 0 | F14: 0 | G14: =F14*E14 -> 0
A15: 1.5 | B15: 0 | C15: =B15/A15 -> 0 | D15: =C15*100 -> 0 | E15: =C15*10 -> 0 | F15: 0 | G15: =F15*E15 -> 0
A16: 1 | B16: 0 | C16: =B16/A16 -> 0 | D16: =C16*100 -> 0 | E16: =C16*10 -> 0 | F16: 0 | G16: =F16*E16 -> 0
A17: 0.5 | B17: 0 | C17: =B17/A17 -> 0 | D17: =C17*100 -> 0 | E17: =C17*10 -> 0 | F17: 0 | G17: =F17*E17 -> 0
A20: MEDIDAS DE MATERIALES ANCHO EN CENTIMETROS | B20: CANTIDAD CM² | C20: CONVERSION DEL ROLLO EN CM | D20: CONVERSION DEL ROLLO EN DM | E20: CONVERSION DEL ROLLO EN M | F20: CANTIDAD DE PRODUCTOS | G20: CANTIDAD TOTAL DE MATERIAL EN M
A21: 145 | B21: =PEDIDO!C4 -> 24 | C21: =B21/A21 -> 0.16551724 | D21: =C21/10 -> 0.016551724 | E21: =C21/100 -> 0.0016551724 | F21: 0 | G21: =F21*E21 -> 0
A22: 145 | B22: =PEDIDO!C5 -> 7000 | C22: =B22/A22 -> 48.275862 | D22: =C22/10 -> 4.8275862 | E22: =C22/100 -> 0.48275862 | F22: 0 | G22: =F22*E22 -> 0
A23: 145 | B23: =PEDIDO!C6 -> 100 | C23: =B23/A23 -> 0.68965517 | D23: =C23/10 -> 0.068965517 | E23: =C23/100 -> 0.0068965517 | F23: 0 | G23: =F23*E23 -> 0
A24: 145 | B24: =PEDIDO!C7 -> 3 | C24: =B24/A24 -> 0.020689655 | D24: =C24/10 -> 0.0020689655 | E24: =C24/100 -> 0.00020689655 | F24: 0 | G24: =F24*E24 -> 0
A25: 145 | B25: =PEDIDO!C8 -> 20 | C25: =B25/A25 -> 0.13793103 | D25: =C25/10 -> 0.013793103 | E25: =C25/100 -> 0.0013793103 | F25: 0 | G25: =F25*E25 -> 0
A26: 145 | B26: =PEDIDO!C9 -> 1 | C26: =B26/A26 -> 0.0068965517 | D26: =C26/10 -> 0.00068965517 | E26: =C26/100 -> 6.8965517e-05 | F26: 0 | G26: =F26*E26 -> 0
A27: 145 | B27: =PEDIDO!C10 -> 7000 | C27: =B27/A27 -> 48.275862 | D27: =C27/10 -> 4.8275862 | E27: =C27/100 -> 0.48275862 | F27: 0 | G27: =F27*E27 -> 0
A28: 145 | B28: =PEDIDO!C11 -> 1200 | C28: =B28/A28 -> 8.2758621 | D28: =C28/10 -> 0.82758621 | E28: =C28/100 -> 0.082758621 | F28: 0 | G28: =F28*E28 -> 0
A29: 145 | B29: =PEDIDO!C12 -> 2 | C29: =B29/A29 -> 0.013793103 | D29: =C29/10 -> 0.0013793103 | E29: =C29/100 -> 0.00013793103 | F29: 0 | G29: =F29*E29 -> 0
A30: 145 | B30: =PEDIDO!C13 -> 7000 | C30: =B30/A30 -> 48.275862 | D30: =C30/10 -> 4.8275862 | E30: =C30/100 -> 0.48275862 | F30: 0 | G30: =F30*E30 -> 0
A31: 145 | B31: =PEDIDO!C14 -> 200 | C31: =B31/A31 -> 1.3793103 | D31: =C31/10 -> 0.13793103 | E31: =C31/100 -> 0.013793103 | F31: 0 | G31: =F31*E31 -> 0
A32: 145 | B32: =PEDIDO!C15 -> 0 | C32: =B32/A32 -> 0 | D32: =C32/10 -> 0 | E32: =C32/100 -> 0 | F32: 0 | G32: =F32*E32 -> 0
... A45: 145 | B45: =PEDIDO!C28 -> 0 | C45: =B45/A45 -> 0 | D45: =C45/10 -> 0 | E45: =C45/100 -> 0 | F45: 0 | G45: =F45*E45 -> 0

Sheet INVENTARIO
A1: MATERIAL | B1: VALOR | C1: CANTIDAD | D1: MEDIDAS DE ANCHO EN CM
A2: Argolla Plastica de 1 1/2"- 40mm ( unidad) | B2: 133.4 | C2: 1
A3: 0 | B3: 0 | C3: 0
A4: argolla para llaveros | B4: 50 | C4: 1
A5: argolla plana 1" ¼ niquel | B5: 1392 | C5: 1
A6: argolla plana 2" niquel | B6: 2204 | C6: 1
A7: argolla 1" niquel | B7: 800 | C7: 1
A8: argolla 1" ¼ niquel | B8: 800 | C8: 1
A9: argolla 1" ½ niquel | B9: 800 | C9: 1
A10: argolla 1" pb | B10: 800 | C10: 1
A11: argolla 1" ½ pb | B11: 800 | C11: 1
A12: Broche Billetera (unidad) | B12: 58 | C12: 1
A13: Broche Cazuela Grande (unidad) | B13: 63.8 | C13: 1
A14: Broche Cazuela Pequeño (unidad) | B14: 63.8 | C14: 1
A15: Broche Iman Grande ( unidad) | B15: 130 | C15: 1
... A65: Espuma multifor densidad 40 de (cm²) | B65: 0.17 | C65: 1
A66: EVA espuma para suelas (cm²) | B66: 0.25 | C66: 1 | D66: 100
A67: Forro Badana Sintetica (cm²) | B67: 0.57 | C67: 1 | D67: 140
A68: Forro Cerdo (Dm2) | B68: 284 | C68: 1
A69: Forro cuero Marquilla (Dm2) | B69: 491 | C69: 1
A70: Forro Malla (cm²) | B70: 0.1 | C70: 1 | D70: 140
A71: Forro para calzado piquet (terry) (cm²) | B71: 0.36 | C71: 1 | D71: 140
A72: hebilla 1" niquel | B72: 928 | C72: 1
A73: hebilla grande 1" ¼ niquel | B73: 1500 | C73: 1
A74: hebilla 1" ¼ niquel | B74: 1000 | C74: 1
A75: hebilla grande 1" ½ niquel | B75: 1100 | C75: 1
A76: hebilla 1" pb | B76: 930 | C76: 1
A77: hebilla 1"¼ pb | B77: 950 | C77: 1
A78: hebilla de cinturon | B78: 2000 | C78: 1
A79: hebilla pequaña niquel | B79: 500 | C79: 1
A80: hebilla ¾ negra | B80: 400 | C80: 1
A81: Hiladilla (cm) | B81: 0.5 | C81: 1
A82: Lambrilla de 3mm (cm²) | B82: 0.25 | C82: 1 | D82: 150
A83: Lambrilla de 4mm (cm²) | B83: 0.51 | C83: 1 | D83: 150
A84: llaves #6 Nq de lujo | B84: 300 | C84: 1
A85: llaves #4 Nq sencillas | B85: 105 | C85: 1
A86: llaves #4 Pb | B86: 105 | C86: 1
A87: llaves #3 Nq Sencillas | B87: 100 | C87: 1
A88: llaves #3 Nq de lujo | B88: 200 | C88: 1
A89: llaves #3 Pb | B89: 100 | C89: 1
...

Sheet Hoja3
A1: PEDIDO MATERIALES
B2: UNIDAD DE COMPRA | C2: VALOR UNIDAD DE COMPRA | D2: CANTIDAD A PEDIR | E2: VALOR TOTAL
A3: interlon (metro) | B3: metro | C3: 1900 | D3: 450 | E3: =C3*D3 -> 855000
A4: cambre de 100gr (metro) | B4: metro | C4: 1380 | D4: 100 | E4: =C4*D4 -> 138000
A5: odena #1 ( hoja) | B5: lámina | C5: 9860 | D5: 20 | E5: =C5*D5 -> 197200
A6: odena vulcan 1.5 ( hoja) | B6: lámina | C6: 10500 | D6: 20 | E6: =C6*D6 -> 210000
A7: odena vulcan 0.5 ( hoja) | B7: lámina | C7: 5800 | D7: 20 | E7: =C7*D7 -> 116000
A8: espuma eva de 15mm colores (hoja) | B8: lámina | C8: 27840 | D8: 10 | E8: =C8*D8 -> 278400
A9: Cartulina bristol 70*100 (pliego) | B9: pliego | C9: 406 | D9: 500 | E9: =C9*D9 -> 203000
A10: bolsa plastica de 12*14 ( unidad) | B10: unnidad | C10: 34.8 | D10: 500 | E10: =C10*D10 -> 17400
A11: Cinta de enmascarar de 1" (royo) | B11: royo | C11: 1774.8 | D11: 150 | E11: =C11*D11 -> 266220
A12: limpiador AT 20 ( galón) | B12: galón | C12: 17840.67 | D12: 12 | E12: =C12*D12 -> 214088.04
A13: pegante - pega 396 ( galón) | B13: galón | C13: 22573.6 | D13: 24 | E13: =C13*D13 -> 541766.4
A14: pegante - solucion de caucho ( galón) | B14: galón | C14: 11321.6 | D14: 24 | E14: =C14*D14 -> 271718.4
... A30: remache tubular # 8 pavonado doble cabeza | B30: millar | C30: 18000 | D30: 1 | E30: =C30*D30 -> 18000
B31: VALOR TOTAL | E31: =SUM(E3:E30) -> 7333792.8
A34: NOTA: Estos valores son tomados del ultimo pedido del 2011
