Workbook

Sheet Hoja1
C1: Referencia: | F1: 2 | I1: Maribel Gil modelista | L1: 0 a 1.5 | M1: 5 | N1: 1.05
C2: Tipo: | F2: cinturon Gym talla S | L2: 1.51 a 3 | M2: 10 | N2: 1.1
C3: Fecha: | F3: 45000 | L3: 3.01 a 5 | M3: 15 | N3: 1.15
C4: cliente | F4: SENA | L4: mas de 5 | M4: 20 | N4: 1.2
C5: numero de ficha | F5: celda de produccion | L5: tiras de mas de 80 cm | M5: 40 | N5: 1.4
A8: material | B8: numero del molde | C8: nombre del molde | D8: cantidad | E8: alto | F8: ancho | G8: alto x ancho = cm_2 | H8: dm_2 | I8: % desperdicio | J8: Total | L8: PENDIENTE FOTO
A9: cuero | B9: 1 | C9: tira | D9: 1 | E9: 97 | F9: 5 | G9: =E9*F9 -> 485 | H9: =G9/100 -> 4.85 | I9: 1.4 | J9: =D9*H9*I9 -> 6.79
B10: 2 | C10: faja | D10: 1 | E10: 83 | F10: 12 | G10: =E10*F10 -> 996 | H10: =G10/100 -> 9.96 | I10: 1.4 | J10: =D10*H10*I10 -> 13.944
B11: 3 | C11: pasador | D11: 2 | E11: 13 | F11: 1.5 | G11: =E11*F11 -> 19.5 | H11: =G11/100 -> 0.195 | I11: 1.05 | J11: =D11*H11*I11 -> 0.4095
G12: =E12*F12 -> 0 | H12: =G12/100 -> 0 | I12: 0 | J12: =D12*H12*I12 -> 0
G13: =E13*F13 -> 0 | H13: =G13/100 -> 0 | I13: 0 | J13: =D13*H13*I13 -> 0
G14: =E14*F14 -> 0 | H14: =G14/100 -> 0 | I14: 0 | J14: =D14*H14*I14 -> 0
G15: =E15*F15 -> 0 | H15: =G15/100 -> 0 | I15: 0 | J15: =D15*H15*I15 -> 0
G16: =E16*F16 -> 0 | H16: =G16/100 -> 0 | I16: 0 | J16: =D16*H16*I16 -> 0
G17: =E17*F17 -> 0 | H17: =G17/100 -> 0 | I17: 0 | J17: =D17*H17*I17 -> 0
G18: =E18*F18 -> 0 | H18: =G18/100 -> 0 | I18: 0 | J18: =D18*H18*I18 -> 0
G19: =E19*F19 -> 0 | H19: =G19/100 -> 0 | I19: 0 | J19: =D19*H19*I19 -> 0
G20: =E20*F20 -> 0 | H20: =G20/100 -> 0 | I20: 0 | J20: =D20*H20*I20 -> 0
G21: =E21*F21 -> 0 | H21: =G21/100 -> 0 | I21: 0 | J21: =D21*H21*I21 -> 0
G22: =E22*F22 -> 0 | H22: =G22/100 -> 0 | I22: 0 | J22: =D22*H22*I22 -> 0
G23: =E23*F23 -> 0 | H23: =G23/100 -> 0 | I23: 0 | J23: =D23*H23*I23 -> 0
... G26: =E26*F26 -> 0 | H26: =G26/100 -> 0 | I26: 0 | J26: =D26*H26*I26 -> 0
B27: total cuero en dm_2 | J27: =SUM(J9:J26) -> 21.1435
A28: perimetros para consumo de hilo en cm | E28: =SUM(E9:E26) -> 193 | F28: =SUM(F9:F26) -> 18.5 | G28: =E28+F28 -> 211.5 | H28: =G28*2 -> 423
A30: material | B30: numero del molde | C30: nombre del molde | D30: cantidad | E30: alto | F30: ancho | G30: atlo x ancho=cm_2 | H30: dm_2 | I30: % desperdicio | J30: Total
A31: forro cerdo | B31: 1 | C31: tira | D31: 1 | E31: 97 | F31: 5 | G31: =E31*F31 -> 485 | H31: =G31/100 -> 4.85 | I31: 1.4 | J31: =D31*H31*I31 -> 6.79
B32: 2 | C32: faja | D32: 1 | E32: 90 | F32: 15 | G32: =E32*F32 -> 1350 | H32: =G32/100 -> 13.5 | I32: 1.05 | J32: =D32*H32*I32 -> 14.175
G33: =E33*F33 -> 0 | H33: =G33/100 -> 0 | I33: 0 | J33: =D33*H33*I33 -> 0
G34: =E34*F34 -> 0 | H34: =G34/100 -> 0 | I34: 0 | J34: =D34*H34*I34 -> 0
G35: =E35*F35 -> 0 | H35: =G35/100 -> 0 | I35: 0 | J35: =D35*H35*I35 -> 0
G36: =E36*F36 -> 0 | H36: =G36/100 -> 0 | I36: 0 | J36: =D36*H36*I36 -> 0
G37: =E37*F37 -> 0 | H37: =G37/100 -> 0 | I37: 0 | J37: =D37*H37*I37 -> 0
J38: =SUM(J31:J37) -> 20.965
A40: material | B40: numero del molde | C40: nombre del molde | D40: cantidad | E40: alto | F40: ancho | G40: atlo x ancho=cm_2 | H40: % desperdicio | I40: Total
A41: salpa 0.8 | B41: 1 | C41: tira | D41: 1 | E41: 97 | F41: 5 | G41: =E41*F41 -> 485 | H41: 1.1 | I41: =D41*G41*H41 -> 533.5
B42: 2 | C42: faja | D42: 1 | E42: 83 | F42: 12 | G42: =E42*F42 -> 996 | H42: 1.1 | I42: =D42*G42*H42 -> 1095.6
G43: =E43*F43 -> 0 | H43: 1.1 | I43: =D43*G43*H43 -> 0
G44: =E44*F44 -> 0 | H44: 1.1 | I44: =D44*G44*H44 -> 0
G45: =E45*F45 -> 0 | H45: 1.1 | I45: =D45*G45*H45 -> 0
G46: =E46*F46 -> 0 | H46: 1.1 | I46: =D46*G46*H46 -> 0
...

Sheet Hoja2
C1: Referencia: | F1: =Hoja1!F1 -> 2 | I1: Maribel Gil modelista
C2: Tipo: | F2: =Hoja1!F2 -> cinturon Gym talla S
C3: Fecha: | F3: =Hoja1!F3 -> 45000
C4: cliente | F4: =Hoja1!F4 -> SENA
C5: numero de ficha | F5: =Hoja1!F5 -> celda de produccion
A8: MATERIAL | B8: UNIDAD DE MEDIDA | C8: CANTIDAD | D8: VALOR UNITARIO | E8: VALOR TOTAL $ | H8: material | I8: unidad de medida compra | J8: valor
A9: =Hoja1!A9 -> cuero | B9: dm_2 | C9: =Hoja1!J27 -> 21.1435 | D9: =J9 -> 0 | E9: =C9*D9 -> 0 | H9: =A9 -> cuero | I9: =B9 -> dm_2 | J9: 0
A10: =Hoja1!A31 -> forro cerdo | B10: dm_2 | C10: =Hoja1!J38 -> 20.965 | D10: =J10 -> 0 | E10: =C10*D10 -> 0 | H10: =A10 -> forro cerdo | I10: =B10 -> dm_2 | J10: 0
A11: =Hoja1!A41 -> salpa 0.8 | B11: cm | C11: =Hoja1!I53/140 -> 11.636429 | D11: =J11/100 -> 0 | E11: =C11*D11 -> 0 | H11: =A11 -> salpa 0.8 | I11: metro | J11: 0
A12: =Hoja1!A56 -> 0 | B12: dm_2 | C12: =Hoja1!J66 -> 0 | D12: =J12 -> 0 | E12: =C12*D12 -> 0 | H12: =A12 -> 0 | I12: metro | J12: 0
A13: =Hoja1!A69 -> yumbolon #10 | B13: cm | C13: =Hoja1!I74/100 -> 2.42 | D13: =J13/100 -> 0 | E13: =C13*D13 -> 0 | H13: =A13 -> yumbolon #10 | I13: metro | J13: 0
A14: =Hoja1!A77 -> 0 | B14: cm | C14: =Hoja1!I83/100 -> 0 | D14: =J14/100 -> 0 | E14: =C14*D14 -> 0 | H14: =A14 -> 0 | I14: unidad | J14: 0
A15: hebilla coscoja doble hebijon de 1 1/2'' | B15: cm | C15: 1 | D15: =J15/100 -> 0 | E15: =C15*D15 -> 0 | H15: =A15 -> hebilla coscoja doble hebijon de 1 1/2'' | I15: unidad | J15: 0
A16: remache tubular #12 | B16: unid | C16: 6 | D16: =J16 -> 0 | E16: =C16*D16 -> 0 | H16: =A16 -> remache tubular #12 | I16: unidad | J16: 0
B17: cm | C17: 0 | D17: =J17/100 -> 0 | E17: =C17*D17 -> 0 | H17: =A17 -> 0 | I17: metro | J17: 0
B18: unid | C18: 0 | D18: =J18 -> 0 | E18: =C18*D18 -> 0 | H18: =A18 -> 0 | I18: unidad | J18: 0
B19: cm | C19: 0 | D19: =J19/100 -> 0 | E19: =C19*D19 -> 0 | H19: =A19 -> 0 | I19: metro | J19: 0
B20: unid | C20: 0 | D20: =J20 -> 0 | E20: =C20*D20 -> 0 | H20: =A20 -> 0 | I20: unidad | J20: 0
B21: unid | C21: 0 | D21: =J21 -> 0 | E21: =C21*D21 -> 0 | H21: =A21 -> 0 | I21: unidad | J21: 0
B22: unid | C22: 0 | D22: =J22 -> 0 | E22: =C22*D22 -> 0 | H22: =A22 -> 0 | I22: unidad | J22: 0
E23: =C23*D23 -> 0 | H23: =A23 -> 0
E24: =C24*D24 -> 0 | H24: =A24 -> 0
A25: hilo x 1500 | B25: metros | C25: =(Hoja1!H28/100)*3 -> 12.69 | D25: =J25/3000 -> 0 | E25: =C25*D25 -> 0 | H25: =A25 -> hilo x 1500 | I25: cono | J25: 0
A26: pegante x 3000 | B26: gramos | C26: 58 | D26: =J26/3000 -> 0 | E26: =C26*D26 -> 0 | H26: =A26 -> pegante x 3000 | I26: galon | J26: 0
A27: mano de obra | C27: 1 | D27: 0 | E27: =C27*D27 -> 0 | H27: =A27 -> mano de obra
A28: empaque | E28: =C28*D28 -> 0 | H28: =A28 -> empaque
A29: inversión | E29: =SUM(E9:E28) -> 0
A30: costos fijos | C30: 0 | E30: =E29*C30 -> 0
A31: costos variables e indirectos | C31: 0 | E31: =E29*C31 -> 0 | G31: punto de equilibrio | H31: minimo de productos que tengo que vender para cumplir con todas las obligaciones sin obtener ganancia
A32: ganancia | C32: 0 | E32: =E29*C32 -> 0
A33: costo sugerido de venta | E33: =SUM(E29:E32) -> 0
A36: tipo de maquina | B36: poste
A37: tipo de aguja | B37: cortante
A38: numero de aguja | B38: 125
A39: calibre hilo | B39: 20
A40: color hilo | B40: beige
A41: corte
A42: prearme
A43: armado
A44: costura
